Workbook

Sheet README
A1: REE minerals — oxide compositions for synthetic LIBS spectra
A3: How to edit
A4: • Edit only the blue numbers in Oxides_typical, Oxides_min and Oxides_max (wt%). Everything else is formulas.
A5: • To add a mineral: add the same row (same row number) to all three Oxides_* sheets, then copy the formula row of Concentrations, Uncertainties and Elements_typical down one row.
A6: • To add an oxide: insert it as a column in Factors (rows 1-4) and in the three Oxides_* sheets at the same column position, and extend the SUMPRODUCT ranges.
A8: Sheets
A9: Oxides_typical / _min / _max — one row per mineral, one column per oxide (wt%). Total = Σ oxides − O≡F,Cl (should be ≈ 98–102).
A10: Factors — oxide → element mass-fraction matrix (from AtomicWeights).
A11: Concentrations + Uncertainties — element wt% in the layout read by data/libs_pipeline.load_sample_types (paths.sample_matrix in the libs_data YAML). Nominal = midpoint of the natural range, uncertainty = half-width, so the generator's uniform draw covers min…max for every element.
A12: Elements_typical — element wt% of the typical analysis (reference only).
A13: Sources — literature / database source of every analysis and range.
A14: Orig_* — the original REE_by_LIBS_tables.xlsx sheets, unchanged.
... A21: Each element is drawn independently in the generator, so drawn compositions are not stoichiometrically coupled (e.g. all REEs high at once is possible).

Sheet AtomicWeights
A1: Element | B1: Atomic weight (u) | C1: In LIBS line DB
A2: O | B2: 15.999 | C2: yes
A3: Si | B3: 28.085 | C3: yes
A4: Ti | B4: 47.867 | C4: yes
A5: Zr | B5: 91.224 | C5: NO
A6: Hf | B6: 178.49 | C6: yes
A7: Sn | B7: 118.71 | C7: yes
A8: Al | B8: 26.981538 | C8: yes
A9: Fe | B9: 55.845 | C9: yes
A10: Mn | B10: 54.938044 | C10: yes
A11: Zn | B11: 65.38 | C11: unverified
A12: Cu | B12: 63.546 | C12: unverified
A13: Mg | B13: 24.305 | C13: yes
... A51: Bi | B51: 208.9804 | C51: yes
A53: Source: IUPAC 2013 standard atomic weights (data/atomic_data.py, ATOMIC_MASS_AMU). 'In LIBS line DB' = element has lines in external_data/Source/LIBS_data.db (QuantParam); elements marked NO are dropped by the generator.

Sheet Factors
A1: Oxide / species | C1: SiO2 | D1: TiO2 | E1: ZrO2 | F1: HfO2 | G1: SnO2 | H1: Al2O3 | I1: Fe2O3 | J1: FeO | K1: MnO | L1: ZnO | M1: Cu2O | N1: MgO | O1: CaO | P1: SrO | Q1: BaO | R1: PbO | S1: Na2O | T1: K2O | U1: Li2O | V1: B2O3 | W1: BeO | X1: Nb2O5 | Y1: Ta2O5 | Z1: WO3 | AA1: P2O5 | AB1: As2O5 | AC1: SO3 | AD1: CO2 | AE1: H2O | AF1: F | AG1: Cl | AH1: S (sulfide) | AI1: ThO2 | AJ1: UO2 | AK1: Sc2O3 | AL1: Y2O3 | AM1: La2O3 | AN1: Ce2O3 | AO1: CeO2 | AP1: Pr2O3 | AQ1: Nd2O3 | AR1: Sm2O3 | AS1: Eu2O3 | AT1: Gd2O3 | AU1: Tb2O3 | AV1: Dy2O3 | AW1: Ho2O3 | AX1: Er2O3 | AY1: Tm2O3 | AZ1: Yb2O3 | BA1: Lu2O3 | BB1: Bi2O3
A2: Cation element | C2: Si | D2: Ti | E2: Zr | F2: Hf | G2: Sn | H2: Al | I2: Fe | J2: Fe | K2: Mn | L2: Zn | M2: Cu | N2: Mg | O2: Ca | P2: Sr | Q2: Ba | R2: Pb | S2: Na | T2: K | U2: Li | V2: B | W2: Be | X2: Nb | Y2: Ta | Z2: W | AA2: P | AB2: As | AC2: S | AD2: C | AE2: H | AF2: F | AG2: Cl | AH2: S | AI2: Th | AJ2: U | AK2: Sc | AL2: Y | AM2: La | AN2: Ce | AO2: Ce | AP2: Pr | AQ2: Nd | AR2: Sm | AS2: Eu | AT2: Gd | AU2: Tb | AV2: Dy | AW2: Ho | AX2: Er | AY2: Tm | AZ2: Yb | BA2: Lu | BB2: Bi
A3: n cation | C3: 1 | D3: 1 | E3: 1 | F3: 1 | G3: 1 | H3: 2 | I3: 2 | J3: 1 | K3: 1 | L3: 1 | M3: 2 | N3: 1 | O3: 1 | P3: 1 | Q3: 1 | R3: 1 | S3: 2 | T3: 2 | U3: 2 | V3: 2 | W3: 1 | X3: 2 | Y3: 2 | Z3: 1 | AA3: 2 | AB3: 2 | AC3: 1 | AD3: 1 | AE3: 2 | AF3: 1 | AG3: 1 | AH3: 1 | AI3: 1 | AJ3: 1 | AK3: 2 | AL3: 2 | AM3: 2 | AN3: 2 | AO3: 1 | AP3: 2 | AQ3: 2 | AR3: 2 | AS3: 2 | AT3: 2 | AU3: 2 | AV3: 2 | AW3: 2 | AX3: 2 | AY3: 2 | AZ3: 2 | BA3: 2 | BB3: 2
A4: n O | C4: 2 | D4: 2 | E4: 2 | F4: 2 | G4: 2 | H4: 3 | I4: 3 | J4: 1 | K4: 1 | L4: 1 | M4: 1 | N4: 1 | O4: 1 | P4: 1 | Q4: 1 | R4: 1 | S4: 1 | T4: 1 | U4: 1 | V4: 3 | W4: 1 | X4: 5 | Y4: 5 | Z4: 3 | AA4: 5 | AB4: 5 | AC4: 3 | AD4: 2 | AE4: 1 | AF4: 0 | AG4: 0 | AH4: 0 | AI4: 2 | AJ4: 2 | AK4: 3 | AL4: 3 | AM4: 3 | AN4: 3 | AO4: 2 | AP4: 3 | AQ4: 3 | AR4: 3 | AS4: 3 | AT4: 3 | AU4: 3 | AV4: 3 | AW4: 3 | AX4: 3 | AY4: 3 | AZ4: 3 | BA4: 3 | BB4: 3
A5: Molar mass (g/mol) | C5: =C3*AtomicWeights!$B$3+C4*AtomicWeights!$B$2 -> 60.083 | D5: =D3*AtomicWeights!$B$4+D4*AtomicWeights!$B$2 -> 79.865 | E5: =E3*AtomicWeights!$B$5+E4*AtomicWeights!$B$2 -> 123.222 | F5: =F3*AtomicWeights!$B$6+F4*AtomicWeights!$B$2 -> 210.488 | G5: =G3*AtomicWeights!$B$7+G4*AtomicWeights!$B$2 -> 150.708 | H5: =H3*AtomicWeights!$B$8+H4*AtomicWeights!$B$2 -> 101.96008 | I5: =I3*AtomicWeights!$B$9+I4*AtomicWeights!$B$2 -> 159.687 | J5: =J3*AtomicWeights!$B$9+J4*AtomicWeights!$B$2 -> 71.844 | K5: =K3*AtomicWeights!$B$10+K4*AtomicWeights!$B$2 -> 70.937044 | L5: =L3*AtomicWeights!$B$11+L4*AtomicWeights!$B$2 -> 81.379 | M5: =M3*AtomicWeights!$B$12+M4*AtomicWeights!$B$2 -> 143.091 | N5: =N3*AtomicWeights!$B$13+N4*AtomicWeights!$B$2 -> 40.304 | O5: =O3*AtomicWeights!$B$14+O4*AtomicWeights!$B$2 -> 56.077 | P5: =P3*AtomicWeights!$B$15+P4*AtomicWeights!$B$2 -> 103.619 | Q5: =Q3*AtomicWeights!$B$16+Q4*AtomicWeights!$B$2 -> 153.326 | R5: =R3*AtomicWeights!$B$17+R4*AtomicWeights!$B$2 -> 223.199 | S5: =S3*AtomicWeights!$B$18+S4*AtomicWeights!$B$2 -> 61.978539 | T5: =T3*AtomicWeights!$B$19+T4*AtomicWeights!$B$2 -> 94.1956 | U5: =U3*AtomicWeights!$B$20+U4*AtomicWeights!$B$2 -> 29.879 | V5: =V3*AtomicWeights!$B$21+V4*AtomicWeights!$B$2 -> 69.617 | W5: =W3*AtomicWeights!$B$22+W4*AtomicWeights!$B$2 -> 25.011183 | X5: =X3*AtomicWeights!$B$23+X4*AtomicWeights!$B$2 -> 265.80774 | Y5: =Y3*AtomicWeights!$B$24+Y4*AtomicWeights!$B$2 -> 441.89076 | Z5: =Z3*AtomicWeights!$B$25+Z4*AtomicWeights!$B$2 -> 231.837 | AA5: =AA3*AtomicWeights!$B$26+AA4*AtomicWeights!$B$2 -> 141.94252 | AB5: =AB3*AtomicWeights!$B$27+AB4*AtomicWeights!$B$2 -> 229.83819 | AC5: =AC3*AtomicWeights!$B$28+AC4*AtomicWeights!$B$2 -> 80.057 | AD5: =AD3*AtomicWeights!$B$29+AD4*AtomicWeights!$B$2 -> 44.009 | AE5: =AE3*AtomicWeights!$B$30+AE4*AtomicWeights!$B$2 -> 18.015 | AF5: =AF3*AtomicWeights!$B$31+AF4*AtomicWeights!$B$2 -> 18.998403 | AG5: =AG3*AtomicWeights!$B$32+AG4*AtomicWeights!$B$2 -> 35.45 | AH5: =AH3*AtomicWeights!$B$28+AH4*AtomicWeights!$B$2 -> 32.06 | AI5: =AI3*AtomicWeights!$B$33+AI4*AtomicWeights!$B$2 -> 264.0357 | AJ5: =AJ3*AtomicWeights!$B$34+AJ4*AtomicWeights!$B$2 -> 270.02691 | AK5: =AK3*AtomicWeights!$B$35+AK4*AtomicWeights!$B$2 -> 137.90882 | AL5: =AL3*AtomicWeights!$B$36+AL4*AtomicWeights!$B$2 -> 225.80868 | AM5: =AM3*AtomicWeights!$B$37+AM4*AtomicWeights!$B$2 -> 325.80794 | AN5: =AN3*AtomicWeights!$B$38+AN4*AtomicWeights!$B$2 -> 328.229 | AO5: =AO3*AtomicWeights!$B$38+AO4*AtomicWeights!$B$2 -> 172.114 | AP5: =AP3*AtomicWeights!$B$39+AP4*AtomicWeights!$B$2 -> 329.81232 | AQ5: =AQ3*AtomicWeights!$B$40+AQ4*AtomicWeights!$B$2 -> 336.481 | AR5: =AR3*AtomicWeights!$B$41+AR4*AtomicWeights!$B$2 -> 348.717 | AS5: =AS3*AtomicWeights!$B$42+AS4*AtomicWeights!$B$2 -> 351.925 | AT5: =AT3*AtomicWeights!$B$43+AT4*AtomicWeights!$B$2 -> 362.497 | AU5: =AU3*AtomicWeights!$B$44+AU4*AtomicWeights!$B$2 -> 365.8477 | AV5: =AV3*AtomicWeights!$B$45+AV4*AtomicWeights!$B$2 -> 372.997 | AW5: =AW3*AtomicWeights!$B$46+AW4*AtomicWeights!$B$2 -> 377.85766 | AX5: =AX3*AtomicWeights!$B$47+AX4*AtomicWeights!$B$2 -> 382.515 | AY5: =AY3*AtomicWeights!$B$48+AY4*AtomicWeights!$B$2 -> 385.86544 | AZ5: =AZ3*AtomicWeights!$B$49+AZ4*AtomicWeights!$B$2 -> 394.087 | BA5: =BA3*AtomicWeights!$B$50+BA4*AtomicWeights!$B$2 -> 397.9306 | BB5: =BB3*AtomicWeights!$B$51+BB4*AtomicWeights!$B$2 -> 465.9578
A6: O factor (g O per g species) | C6: =C4*AtomicWeights!$B$2/C5 -> 0.53256329 | D6: =D4*AtomicWeights!$B$2/D5 -> 0.4006511 | E6: =E4*AtomicWeights!$B$2/E5 -> 0.25967765 | F6: =F4*AtomicWeights!$B$2/F5 -> 0.15201817 | G6: =G4*AtomicWeights!$B$2/G5 -> 0.21231786 | H6: =H4*AtomicWeights!$B$2/H5 -> 0.47074307 | I6: =I4*AtomicWeights!$B$2/I5 -> 0.30056924 | J6: =J4*AtomicWeights!$B$2/J5 -> 0.22269083 | ... AE6: =AE4*AtomicWeights!$B$2/AE5 -> 0.88809326 | AF6: =-AtomicWeights!$B$2/(2*AtomicWeights!$B$31) -> -0.4210617 | AG6: =-AtomicWeights!$B$2/(2*AtomicWeights!$B$32) -> -0.22565585 | AH6: =-AtomicWeights!$B$2/AtomicWeights!$B$28 -> -0.49903306 | AI6: =AI4*AtomicWeights!$B$2/AI5 -> 0.12118816 | AJ6: =AJ4*AtomicWeights!$B$2/AJ5 -> 0.1184993 | AK6: =AK4*AtomicWeights!$B$2/AK5 -> 0.34803431 | AL6: =AL4*AtomicWeights!$B$2/AL5 -> 0.21255605 | AM6: =AM4*AtomicWeights!$B$2/AM5 -> 0.14731685 | AN6: =AN4*AtomicWeights!$B$2/AN5 -> 0.14623022 | AO6: =AO4*AtomicWeights!$B$2/AO5 -> 0.18591166 | AP6: =AP4*AtomicWeights!$B$2/AP5 -> 0.14552822 | ... BB6: =BB4*AtomicWeights!$B$2/BB5 -> 0.10300718
A8: Element | B8: In LIBS line DB | C8: SiO2 | D8: TiO2 | E8: ZrO2 | F8: HfO2 | G8: SnO2 | H8: Al2O3 | I8: Fe2O3 | J8: FeO | K8: MnO | L8: ZnO | M8: Cu2O | N8: MgO | O8: CaO | P8: SrO | Q8: BaO | R8: PbO | S8: Na2O | T8: K2O | U8: Li2O | V8: B2O3 | W8: BeO | X8: Nb2O5 | Y8: Ta2O5 | Z8: WO3 | AA8: P2O5 | AB8: As2O5 | AC8: SO3 | AD8: CO2 | AE8: H2O | AF8: F | AG8: Cl | AH8: S (sulfide) | AI8: ThO2 | AJ8: UO2 | AK8: Sc2O3 | AL8: Y2O3 | AM8: La2O3 | AN8: Ce2O3 | AO8: CeO2 | AP8: Pr2O3 | AQ8: Nd2O3 | AR8: Sm2O3 | AS8: Eu2O3 | AT8: Gd2O3 | AU8: Tb2O3 | AV8: Dy2O3 | AW8: Ho2O3 | AX8: Er2O3 | AY8: Tm2O3 | AZ8: Yb2O3 | BA8: Lu2O3 | BB8: Bi2O3
A9: O | B9: =AtomicWeights!$C$2 -> yes | C9: =C$6 -> 0.53256329 | D9: =D$6 -> 0.4006511 | E9: =E$6 -> 0.25967765 | F9: =F$6 -> 0.15201817 | G9: =G$6 -> 0.21231786 | H9: =H$6 -> 0.47074307 | I9: =I$6 -> 0.30056924 | J9: =J$6 -> 0.22269083 | ... BB9: =BB$6 -> 0.10300718
A10: Si | B10: =AtomicWeights!$C$3 -> yes | C10: =IF(C$2=$A10,C$3*AtomicWeights!$B$3/C$5,0) -> 0.46743671 | D10: =IF(D$2=$A10,D$3*AtomicWeights!$B$3/D$5,0) -> 0 | E10: =IF(E$2=$A10,E$3*AtomicWeights!$B$3/E$5,0) -> 0 | F10: =IF(F$2=$A10,F$3*AtomicWeights!$B$3/F$5,0) -> 0 | G10: =IF(G$2=$A10,G$3*AtomicWeights!$B$3/G$5,0) -> 0 | H10: =IF(H$2=$A10,H$3*AtomicWeights!$B$3/H$5,0) -> 0 | I10: =IF(I$2=$A10,I$3*AtomicWeights!$B$3/I$5,0) -> 0 | J10: =IF(J$2=$A10,J$3*AtomicWeights!$B$3/J$5,0) -> 0 | ... BB10: =IF(BB$2=$A10,BB$3*AtomicWeights!$B$3/BB$5,0) -> 0
A11: Ti | B11: =AtomicWeights!$C$4 -> yes | C11: =IF(C$2=$A11,C$3*AtomicWeights!$B$4/C$5,0) -> 0 | D11: =IF(D$2=$A11,D$3*AtomicWeights!$B$4/D$5,0) -> 0.5993489 | E11: =IF(E$2=$A11,E$3*AtomicWeights!$B$4/E$5,0) -> 0 | F11: =IF(F$2=$A11,F$3*AtomicWeights!$B$4/F$5,0) -> 0 | G11: =IF(G$2=$A11,G$3*AtomicWeights!$B$4/G$5,0) -> 0 | H11: =IF(H$2=$A11,H$3*AtomicWeights!$B$4/H$5,0) -> 0 | I11: =IF(I$2=$A11,I$3*AtomicWeights!$B$4/I$5,0) -> 0 | J11: =IF(J$2=$A11,J$3*AtomicWeights!$B$4/J$5,0) -> 0 | ... BB11: =IF(BB$2=$A11,BB$3*AtomicWeights!$B$4/BB$5,0) -> 0
A12: Zr | B12: =AtomicWeights!$C$5 -> NO | C12: =IF(C$2=$A12,C$3*AtomicWeights!$B$5/C$5,0) -> 0 | D12: =IF(D$2=$A12,D$3*AtomicWeights!$B$5/D$5,0) -> 0 | E12: =IF(E$2=$A12,E$3*AtomicWeights!$B$5/E$5,0) -> 0.74032235 | F12: =IF(F$2=$A12,F$3*AtomicWeights!$B$5/F$5,0) -> 0 | G12: =IF(G$2=$A12,G$3*AtomicWeights!$B$5/G$5,0) -> 0 | H12: =IF(H$2=$A12,H$3*AtomicWeights!$B$5/H$5,0) -> 0 | I12: =IF(I$2=$A12,I$3*AtomicWeights!$B$5/I$5,0) -> 0 | J12: =IF(J$2=$A12,J$3*AtomicWeights!$B$5/J$5,0) -> 0 | ... BB12: =IF(BB$2=$A12,BB$3*AtomicWeights!$B$5/BB$5,0) -> 0
A13: Hf | B13: =AtomicWeights!$C$6 -> yes | C13: =IF(C$2=$A13,C$3*AtomicWeights!$B$6/C$5,0) -> 0 | D13: =IF(D$2=$A13,D$3*AtomicWeights!$B$6/D$5,0) -> 0 | E13: =IF(E$2=$A13,E$3*AtomicWeights!$B$6/E$5,0) -> 0 | F13: =IF(F$2=$A13,F$3*AtomicWeights!$B$6/F$5,0) -> 0.84798183 | G13: =IF(G$2=$A13,G$3*AtomicWeights!$B$6/G$5,0) -> 0 | H13: =IF(H$2=$A13,H$3*AtomicWeights!$B$6/H$5,0) -> 0 | I13: =IF(I$2=$A13,I$3*AtomicWeights!$B$6/I$5,0) -> 0 | J13: =IF(J$2=$A13,J$3*AtomicWeights!$B$6/J$5,0) -> 0 | ... BB13: =IF(BB$2=$A13,BB$3*AtomicWeights!$B$6/BB$5,0) -> 0
A14: Sn | B14: =AtomicWeights!$C$7 -> yes | C14: =IF(C$2=$A14,C$3*AtomicWeights!$B$7/C$5,0) -> 0 | D14: =IF(D$2=$A14,D$3*AtomicWeights!$B$7/D$5,0) -> 0 | E14: =IF(E$2=$A14,E$3*AtomicWeights!$B$7/E$5,0) -> 0 | F14: =IF(F$2=$A14,F$3*AtomicWeights!$B$7/F$5,0) -> 0 | G14: =IF(G$2=$A14,G$3*AtomicWeights!$B$7/G$5,0) -> 0.78768214 | H14: =IF(H$2=$A14,H$3*AtomicWeights!$B$7/H$5,0) -> 0 | I14: =IF(I$2=$A14,I$3*AtomicWeights!$B$7/I$5,0) -> 0 | J14: =IF(J$2=$A14,J$3*AtomicWeights!$B$7/J$5,0) -> 0 | ... BB14: =IF(BB$2=$A14,BB$3*AtomicWeights!$B$7/BB$5,0) -> 0
A15: Al | B15: =AtomicWeights!$C$8 -> yes | C15: =IF(C$2=$A15,C$3*AtomicWeights!$B$8/C$5,0) -> 0 | D15: =IF(D$2=$A15,D$3*AtomicWeights!$B$8/D$5,0) -> 0 | E15: =IF(E$2=$A15,E$3*AtomicWeights!$B$8/E$5,0) -> 0 | F15: =IF(F$2=$A15,F$3*AtomicWeights!$B$8/F$5,0) -> 0 | G15: =IF(G$2=$A15,G$3*AtomicWeights!$B$8/G$5,0) -> 0 | H15: =IF(H$2=$A15,H$3*AtomicWeights!$B$8/H$5,0) -> 0.52925693 | I15: =IF(I$2=$A15,I$3*AtomicWeights!$B$8/I$5,0) -> 0 | J15: =IF(J$2=$A15,J$3*AtomicWeights!$B$8/J$5,0) -> 0 | ... BB15: =IF(BB$2=$A15,BB$3*AtomicWeights!$B$8/BB$5,0) -> 0
A16: Fe | B16: =AtomicWeights!$C$9 -> yes | C16: =IF(C$2=$A16,C$3*AtomicWeights!$B$9/C$5,0) -> 0 | D16: =IF(D$2=$A16,D$3*AtomicWeights!$B$9/D$5,0) -> 0 | E16: =IF(E$2=$A16,E$3*AtomicWeights!$B$9/E$5,0) -> 0 | F16: =IF(F$2=$A16,F$3*AtomicWeights!$B$9/F$5,0) -> 0 | G16: =IF(G$2=$A16,G$3*AtomicWeights!$B$9/G$5,0) -> 0 | H16: =IF(H$2=$A16,H$3*AtomicWeights!$B$9/H$5,0) -> 0 | I16: =IF(I$2=$A16,I$3*AtomicWeights!$B$9/I$5,0) -> 0.69943076 | J16: =IF(J$2=$A16,J$3*AtomicWeights!$B$9/J$5,0) -> 0.77730917 | ... BB16: =IF(BB$2=$A16,BB$3*AtomicWeights!$B$9/BB$5,0) -> 0
A17: Mn | B17: =AtomicWeights!$C$10 -> yes | C17: =IF(C$2=$A17,C$3*AtomicWeights!$B$10/C$5,0) -> 0 | D17: =IF(D$2=$A17,D$3*AtomicWeights!$B$10/D$5,0) -> 0 | E17: =IF(E$2=$A17,E$3*AtomicWeights!$B$10/E$5,0) -> 0 | F17: =IF(F$2=$A17,F$3*AtomicWeights!$B$10/F$5,0) -> 0 | G17: =IF(G$2=$A17,G$3*AtomicWeights!$B$10/G$5,0) -> 0 | H17: =IF(H$2=$A17,H$3*AtomicWeights!$B$10/H$5,0) -> 0 | I17: =IF(I$2=$A17,I$3*AtomicWeights!$B$10/I$5,0) -> 0 | J17: =IF(J$2=$A17,J$3*AtomicWeights!$B$10/J$5,0) -> 0 | ... BB17: =IF(BB$2=$A17,BB$3*AtomicWeights!$B$10/BB$5,0) -> 0
A18: Zn | B18: =AtomicWeights!$C$11 -> unverified | C18: =IF(C$2=$A18,C$3*AtomicWeights!$B$11/C$5,0) -> 0 | D18: =IF(D$2=$A18,D$3*AtomicWeights!$B$11/D$5,0) -> 0 | E18: =IF(E$2=$A18,E$3*AtomicWeights!$B$11/E$5,0) -> 0 | F18: =IF(F$2=$A18,F$3*AtomicWeights!$B$11/F$5,0) -> 0 | G18: =IF(G$2=$A18,G$3*AtomicWeights!$B$11/G$5,0) -> 0 | H18: =IF(H$2=$A18,H$3*AtomicWeights!$B$11/H$5,0) -> 0 | I18: =IF(I$2=$A18,I$3*AtomicWeights!$B$11/I$5,0) -> 0 | J18: =IF(J$2=$A18,J$3*AtomicWeights!$B$11/J$5,0) -> 0 | ... BB18: =IF(BB$2=$A18,BB$3*AtomicWeights!$B$11/BB$5,0) -> 0
A19: Cu | B19: =AtomicWeights!$C$12 -> unverified | C19: =IF(C$2=$A19,C$3*AtomicWeights!$B$12/C$5,0) -> 0 | D19: =IF(D$2=$A19,D$3*AtomicWeights!$B$12/D$5,0) -> 0 | E19: =IF(E$2=$A19,E$3*AtomicWeights!$B$12/E$5,0) -> 0 | F19: =IF(F$2=$A19,F$3*AtomicWeights!$B$12/F$5,0) -> 0 | G19: =IF(G$2=$A19,G$3*AtomicWeights!$B$12/G$5,0) -> 0 | H19: =IF(H$2=$A19,H$3*AtomicWeights!$B$12/H$5,0) -> 0 | I19: =IF(I$2=$A19,I$3*AtomicWeights!$B$12/I$5,0) -> 0 | J19: =IF(J$2=$A19,J$3*AtomicWeights!$B$12/J$5,0) -> 0 | ... BB19: =IF(BB$2=$A19,BB$3*AtomicWeights!$B$12/BB$5,0) -> 0
A20: Mg | B20: =AtomicWeights!$C$13 -> yes | C20: =IF(C$2=$A20,C$3*AtomicWeights!$B$13/C$5,0) -> 0 | D20: =IF(D$2=$A20,D$3*AtomicWeights!$B$13/D$5,0) -> 0 | E20: =IF(E$2=$A20,E$3*AtomicWeights!$B$13/E$5,0) -> 0 | F20: =IF(F$2=$A20,F$3*AtomicWeights!$B$13/F$5,0) -> 0 | G20: =IF(G$2=$A20,G$3*AtomicWeights!$B$13/G$5,0) -> 0 | H20: =IF(H$2=$A20,H$3*AtomicWeights!$B$13/H$5,0) -> 0 | I20: =IF(I$2=$A20,I$3*AtomicWeights!$B$13/I$5,0) -> 0 | J20: =IF(J$2=$A20,J$3*AtomicWeights!$B$13/J$5,0) -> 0 | ... BB20: =IF(BB$2=$A20,BB$3*AtomicWeights!$B$13/BB$5,0) -> 0
A21: Ca | B21: =AtomicWeights!$C$14 -> yes | C21: =IF(C$2=$A21,C$3*AtomicWeights!$B$14/C$5,0) -> 0 | D21: =IF(D$2=$A21,D$3*AtomicWeights!$B$14/D$5,0) -> 0 | E21: =IF(E$2=$A21,E$3*AtomicWeights!$B$14/E$5,0) -> 0 | F21: =IF(F$2=$A21,F$3*AtomicWeights!$B$14/F$5,0) -> 0 | G21: =IF(G$2=$A21,G$3*AtomicWeights!$B$14/G$5,0) -> 0 | H21: =IF(H$2=$A21,H$3*AtomicWeights!$B$14/H$5,0) -> 0 | I21: =IF(I$2=$A21,I$3*AtomicWeights!$B$14/I$5,0) -> 0 | J21: =IF(J$2=$A21,J$3*AtomicWeights!$B$14/J$5,0) -> 0 | ... BB21: =IF(BB$2=$A21,BB$3*AtomicWeights!$B$14/BB$5,0) -> 0
A22: Sr | B22: =AtomicWeights!$C$15 -> yes | C22: =IF(C$2=$A22,C$3*AtomicWeights!$B$15/C$5,0) -> 0 | D22: =IF(D$2=$A22,D$3*AtomicWeights!$B$15/D$5,0) -> 0 | E22: =IF(E$2=$A22,E$3*AtomicWeights!$B$15/E$5,0) -> 0 | F22: =IF(F$2=$A22,F$3*AtomicWeights!$B$15/F$5,0) -> 0 | G22: =IF(G$2=$A22,G$3*AtomicWeights!$B$15/G$5,0) -> 0 | H22: =IF(H$2=$A22,H$3*AtomicWeights!$B$15/H$5,0) -> 0 | I22: =IF(I$2=$A22,I$3*AtomicWeights!$B$15/I$5,0) -> 0 | J22: =IF(J$2=$A22,J$3*AtomicWeights!$B$15/J$5,0) -> 0 | ... BB22: =IF(BB$2=$A22,BB$3*AtomicWeights!$B$15/BB$5,0) -> 0
A23: Ba | B23: =AtomicWeights!$C$16 -> yes | C23: =IF(C$2=$A23,C$3*AtomicWeights!$B$16/C$5,0) -> 0 | D23: =IF(D$2=$A23,D$3*AtomicWeights!$B$16/D$5,0) -> 0 | E23: =IF(E$2=$A23,E$3*AtomicWeights!$B$16/E$5,0) -> 0 | F23: =IF(F$2=$A23,F$3*AtomicWeights!$B$16/F$5,0) -> 0 | G23: =IF(G$2=$A23,G$3*AtomicWeights!$B$16/G$5,0) -> 0 | H23: =IF(H$2=$A23,H$3*AtomicWeights!$B$16/H$5,0) -> 0 | I23: =IF(I$2=$A23,I$3*AtomicWeights!$B$16/I$5,0) -> 0 | J23: =IF(J$2=$A23,J$3*AtomicWeights!$B$16/J$5,0) -> 0 | ... BB23: =IF(BB$2=$A23,BB$3*AtomicWeights!$B$16/BB$5,0) -> 0
A24: Pb | B24: =AtomicWeights!$C$17 -> yes | C24: =IF(C$2=$A24,C$3*AtomicWeights!$B$17/C$5,0) -> 0 | D24: =IF(D$2=$A24,D$3*AtomicWeights!$B$17/D$5,0) -> 0 | E24: =IF(E$2=$A24,E$3*AtomicWeights!$B$17/E$5,0) -> 0 | F24: =IF(F$2=$A24,F$3*AtomicWeights!$B$17/F$5,0) -> 0 | G24: =IF(G$2=$A24,G$3*AtomicWeights!$B$17/G$5,0) -> 0 | H24: =IF(H$2=$A24,H$3*AtomicWeights!$B$17/H$5,0) -> 0 | I24: =IF(I$2=$A24,I$3*AtomicWeights!$B$17/I$5,0) -> 0 | J24: =IF(J$2=$A24,J$3*AtomicWeights!$B$17/J$5,0) -> 0 | ... BB24: =IF(BB$2=$A24,BB$3*AtomicWeights!$B$17/BB$5,0) -> 0
A25: Na | B25: =AtomicWeights!$C$18 -> yes | C25: =IF(C$2=$A25,C$3*AtomicWeights!$B$18/C$5,0) -> 0 | D25: =IF(D$2=$A25,D$3*AtomicWeights!$B$18/D$5,0) -> 0 | E25: =IF(E$2=$A25,E$3*AtomicWeights!$B$18/E$5,0) -> 0 | F25: =IF(F$2=$A25,F$3*AtomicWeights!$B$18/F$5,0) -> 0 | G25: =IF(G$2=$A25,G$3*AtomicWeights!$B$18/G$5,0) -> 0 | H25: =IF(H$2=$A25,H$3*AtomicWeights!$B$18/H$5,0) -> 0 | I25: =IF(I$2=$A25,I$3*AtomicWeights!$B$18/I$5,0) -> 0 | J25: =IF(J$2=$A25,J$3*AtomicWeights!$B$18/J$5,0) -> 0 | ... BB25: =IF(BB$2=$A25,BB$3*AtomicWeights!$B$18/BB$5,0) -> 0
A26: K | B26: =AtomicWeights!$C$19 -> yes | C26: =IF(C$2=$A26,C$3*AtomicWeights!$B$19/C$5,0) -> 0 | D26: =IF(D$2=$A26,D$3*AtomicWeights!$B$19/D$5,0) -> 0 | E26: =IF(E$2=$A26,E$3*AtomicWeights!$B$19/E$5,0) -> 0 | F26: =IF(F$2=$A26,F$3*AtomicWeights!$B$19/F$5,0) -> 0 | G26: =IF(G$2=$A26,G$3*AtomicWeights!$B$19/G$5,0) -> 0 | H26: =IF(H$2=$A26,H$3*AtomicWeights!$B$19/H$5,0) -> 0 | I26: =IF(I$2=$A26,I$3*AtomicWeights!$B$19/I$5,0) -> 0 | J26: =IF(J$2=$A26,J$3*AtomicWeights!$B$19/J$5,0) -> 0 | ... BB26: =IF(BB$2=$A26,BB$3*AtomicWeights!$B$19/BB$5,0) -> 0
A27: Li | B27: =AtomicWeights!$C$20 -> unverified | C27: =IF(C$2=$A27,C$3*AtomicWeights!$B$20/C$5,0) -> 0 | D27: =IF(D$2=$A27,D$3*AtomicWeights!$B$20/D$5,0) -> 0 | E27: =IF(E$2=$A27,E$3*AtomicWeights!$B$20/E$5,0) -> 0 | F27: =IF(F$2=$A27,F$3*AtomicWeights!$B$20/F$5,0) -> 0 | G27: =IF(G$2=$A27,G$3*AtomicWeights!$B$20/G$5,0) -> 0 | H27: =IF(H$2=$A27,H$3*AtomicWeights!$B$20/H$5,0) -> 0 | I27: =IF(I$2=$A27,I$3*AtomicWeights!$B$20/I$5,0) -> 0 | J27: =IF(J$2=$A27,J$3*AtomicWeights!$B$20/J$5,0) -> 0 | ... BB27: =IF(BB$2=$A27,BB$3*AtomicWeights!$B$20/BB$5,0) -> 0
A28: B | B28: =AtomicWeights!$C$21 -> unverified | C28: =IF(C$2=$A28,C$3*AtomicWeights!$B$21/C$5,0) -> 0 | D28: =IF(D$2=$A28,D$3*AtomicWeights!$B$21/D$5,0) -> 0 | E28: =IF(E$2=$A28,E$3*AtomicWeights!$B$21/E$5,0) -> 0 | F28: =IF(F$2=$A28,F$3*AtomicWeights!$B$21/F$5,0) -> 0 | G28: =IF(G$2=$A28,G$3*AtomicWeights!$B$21/G$5,0) -> 0 | H28: =IF(H$2=$A28,H$3*AtomicWeights!$B$21/H$5,0) -> 0 | I28: =IF(I$2=$A28,I$3*AtomicWeights!$B$21/I$5,0) -> 0 | J28: =IF(J$2=$A28,J$3*AtomicWeights!$B$21/J$5,0) -> 0 | ... BB28: =IF(BB$2=$A28,BB$3*AtomicWeights!$B$21/BB$5,0) -> 0
A29: Be | B29: =AtomicWeights!$C$22 -> yes | C29: =IF(C$2=$A29,C$3*AtomicWeights!$B$22/C$5,0) -> 0 | D29: =IF(D$2=$A29,D$3*AtomicWeights!$B$22/D$5,0) -> 0 | E29: =IF(E$2=$A29,E$3*AtomicWeights!$B$22/E$5,0) -> 0 | F29: =IF(F$2=$A29,F$3*AtomicWeights!$B$22/F$5,0) -> 0 | G29: =IF(G$2=$A29,G$3*AtomicWeights!$B$22/G$5,0) -> 0 | H29: =IF(H$2=$A29,H$3*AtomicWeights!$B$22/H$5,0) -> 0 | I29: =IF(I$2=$A29,I$3*AtomicWeights!$B$22/I$5,0) -> 0 | J29: =IF(J$2=$A29,J$3*AtomicWeights!$B$22/J$5,0) -> 0 | ... BB29: =IF(BB$2=$A29,BB$3*AtomicWeights!$B$22/BB$5,0) -> 0
A30: Nb | B30: =AtomicWeights!$C$23 -> NO | C30: =IF(C$2=$A30,C$3*AtomicWeights!$B$23/C$5,0) -> 0 | D30: =IF(D$2=$A30,D$3*AtomicWeights!$B$23/D$5,0) -> 0 | E30: =IF(E$2=$A30,E$3*AtomicWeights!$B$23/E$5,0) -> 0 | F30: =IF(F$2=$A30,F$3*AtomicWeights!$B$23/F$5,0) -> 0 | G30: =IF(G$2=$A30,G$3*AtomicWeights!$B$23/G$5,0) -> 0 | H30: =IF(H$2=$A30,H$3*AtomicWeights!$B$23/H$5,0) -> 0 | I30: =IF(I$2=$A30,I$3*AtomicWeights!$B$23/I$5,0) -> 0 | J30: =IF(J$2=$A30,J$3*AtomicWeights!$B$23/J$5,0) -> 0 | ... BB30: =IF(BB$2=$A30,BB$3*AtomicWeights!$B$23/BB$5,0) -> 0
A31: Ta | B31: =AtomicWeights!$C$24 -> yes | C31: =IF(C$2=$A31,C$3*AtomicWeights!$B$24/C$5,0) -> 0 | D31: =IF(D$2=$A31,D$3*AtomicWeights!$B$24/D$5,0) -> 0 | E31: =IF(E$2=$A31,E$3*AtomicWeights!$B$24/E$5,0) -> 0 | F31: =IF(F$2=$A31,F$3*AtomicWeights!$B$24/F$5,0) -> 0 | G31: =IF(G$2=$A31,G$3*AtomicWeights!$B$24/G$5,0) -> 0 | H31: =IF(H$2=$A31,H$3*AtomicWeights!$B$24/H$5,0) -> 0 | I31: =IF(I$2=$A31,I$3*AtomicWeights!$B$24/I$5,0) -> 0 | J31: =IF(J$2=$A31,J$3*AtomicWeights!$B$24/J$5,0) -> 0 | ... BB31: =IF(BB$2=$A31,BB$3*AtomicWeights!$B$24/BB$5,0) -> 0
A32: W | B32: =AtomicWeights!$C$25 -> yes | C32: =IF(C$2=$A32,C$3*AtomicWeights!$B$25/C$5,0) -> 0 | D32: =IF(D$2=$A32,D$3*AtomicWeights!$B$25/D$5,0) -> 0 | E32: =IF(E$2=$A32,E$3*AtomicWeights!$B$25/E$5,0) -> 0 | F32: =IF(F$2=$A32,F$3*AtomicWeights!$B$25/F$5,0) -> 0 | G32: =IF(G$2=$A32,G$3*AtomicWeights!$B$25/G$5,0) -> 0 | H32: =IF(H$2=$A32,H$3*AtomicWeights!$B$25/H$5,0) -> 0 | I32: =IF(I$2=$A32,I$3*AtomicWeights!$B$25/I$5,0) -> 0 | J32: =IF(J$2=$A32,J$3*AtomicWeights!$B$25/J$5,0) -> 0 | ... BB32: =IF(BB$2=$A32,BB$3*AtomicWeights!$B$25/BB$5,0) -> 0
A33: P | B33: =AtomicWeights!$C$26 -> yes | C33: =IF(C$2=$A33,C$3*AtomicWeights!$B$26/C$5,0) -> 0 | D33: =IF(D$2=$A33,D$3*AtomicWeights!$B$26/D$5,0) -> 0 | E33: =IF(E$2=$A33,E$3*AtomicWeights!$B$26/E$5,0) -> 0 | F33: =IF(F$2=$A33,F$3*AtomicWeights!$B$26/F$5,0) -> 0 | G33: =IF(G$2=$A33,G$3*AtomicWeights!$B$26/G$5,0) -> 0 | H33: =IF(H$2=$A33,H$3*AtomicWeights!$B$26/H$5,0) -> 0 | I33: =IF(I$2=$A33,I$3*AtomicWeights!$B$26/I$5,0) -> 0 | J33: =IF(J$2=$A33,J$3*AtomicWeights!$B$26/J$5,0) -> 0 | ... BB33: =IF(BB$2=$A33,BB$3*AtomicWeights!$B$26/BB$5,0) -> 0
A34: As | B34: =AtomicWeights!$C$27 -> yes | C34: =IF(C$2=$A34,C$3*AtomicWeights!$B$27/C$5,0) -> 0 | D34: =IF(D$2=$A34,D$3*AtomicWeights!$B$27/D$5,0) -> 0 | E34: =IF(E$2=$A34,E$3*AtomicWeights!$B$27/E$5,0) -> 0 | F34: =IF(F$2=$A34,F$3*AtomicWeights!$B$27/F$5,0) -> 0 | G34: =IF(G$2=$A34,G$3*AtomicWeights!$B$27/G$5,0) -> 0 | H34: =IF(H$2=$A34,H$3*AtomicWeights!$B$27/H$5,0) -> 0 | I34: =IF(I$2=$A34,I$3*AtomicWeights!$B$27/I$5,0) -> 0 | J34: =IF(J$2=$A34,J$3*AtomicWeights!$B$27/J$5,0) -> 0 | ... BB34: =IF(BB$2=$A34,BB$3*AtomicWeights!$B$27/BB$5,0) -> 0
A35: S | B35: =AtomicWeights!$C$28 -> yes | C35: =IF(C$2=$A35,C$3*AtomicWeights!$B$28/C$5,0) -> 0 | D35: =IF(D$2=$A35,D$3*AtomicWeights!$B$28/D$5,0) -> 0 | E35: =IF(E$2=$A35,E$3*AtomicWeights!$B$28/E$5,0) -> 0 | F35: =IF(F$2=$A35,F$3*AtomicWeights!$B$28/F$5,0) -> 0 | G35: =IF(G$2=$A35,G$3*AtomicWeights!$B$28/G$5,0) -> 0 | H35: =IF(H$2=$A35,H$3*AtomicWeights!$B$28/H$5,0) -> 0 | I35: =IF(I$2=$A35,I$3*AtomicWeights!$B$28/I$5,0) -> 0 | J35: =IF(J$2=$A35,J$3*AtomicWeights!$B$28/J$5,0) -> 0 | ... BB35: =IF(BB$2=$A35,BB$3*AtomicWeights!$B$28/BB$5,0) -> 0
A36: C | B36: =AtomicWeights!$C$29 -> yes | C36: =IF(C$2=$A36,C$3*AtomicWeights!$B$29/C$5,0) -> 0 | D36: =IF(D$2=$A36,D$3*AtomicWeights!$B$29/D$5,0) -> 0 | E36: =IF(E$2=$A36,E$3*AtomicWeights!$B$29/E$5,0) -> 0 | F36: =IF(F$2=$A36,F$3*AtomicWeights!$B$29/F$5,0) -> 0 | G36: =IF(G$2=$A36,G$3*AtomicWeights!$B$29/G$5,0) -> 0 | H36: =IF(H$2=$A36,H$3*AtomicWeights!$B$29/H$5,0) -> 0 | I36: =IF(I$2=$A36,I$3*AtomicWeights!$B$29/I$5,0) -> 0 | J36: =IF(J$2=$A36,J$3*AtomicWeights!$B$29/J$5,0) -> 0 | ... BB36: =IF(BB$2=$A36,BB$3*AtomicWeights!$B$29/BB$5,0) -> 0
A37: H | B37: =AtomicWeights!$C$30 -> yes | C37: =IF(C$2=$A37,C$3*AtomicWeights!$B$30/C$5,0) -> 0 | D37: =IF(D$2=$A37,D$3*AtomicWeights!$B$30/D$5,0) -> 0 | E37: =IF(E$2=$A37,E$3*AtomicWeights!$B$30/E$5,0) -> 0 | F37: =IF(F$2=$A37,F$3*AtomicWeights!$B$30/F$5,0) -> 0 | G37: =IF(G$2=$A37,G$3*AtomicWeights!$B$30/G$5,0) -> 0 | H37: =IF(H$2=$A37,H$3*AtomicWeights!$B$30/H$5,0) -> 0 | I37: =IF(I$2=$A37,I$3*AtomicWeights!$B$30/I$5,0) -> 0 | J37: =IF(J$2=$A37,J$3*AtomicWeights!$B$30/J$5,0) -> 0 | ... BB37: =IF(BB$2=$A37,BB$3*AtomicWeights!$B$30/BB$5,0) -> 0
A38: F | B38: =AtomicWeights!$C$31 -> yes | C38: =IF(C$2=$A38,C$3*AtomicWeights!$B$31/C$5,0) -> 0 | D38: =IF(D$2=$A38,D$3*AtomicWeights!$B$31/D$5,0) -> 0 | E38: =IF(E$2=$A38,E$3*AtomicWeights!$B$31/E$5,0) -> 0 | F38: =IF(F$2=$A38,F$3*AtomicWeights!$B$31/F$5,0) -> 0 | G38: =IF(G$2=$A38,G$3*AtomicWeights!$B$31/G$5,0) -> 0 | H38: =IF(H$2=$A38,H$3*AtomicWeights!$B$31/H$5,0) -> 0 | I38: =IF(I$2=$A38,I$3*AtomicWeights!$B$31/I$5,0) -> 0 | J38: =IF(J$2=$A38,J$3*AtomicWeights!$B$31/J$5,0) -> 0 | ... BB38: =IF(BB$2=$A38,BB$3*AtomicWeights!$B$31/BB$5,0) -> 0
A39: Cl | B39: =AtomicWeights!$C$32 -> yes | C39: =IF(C$2=$A39,C$3*AtomicWeights!$B$32/C$5,0) -> 0 | D39: =IF(D$2=$A39,D$3*AtomicWeights!$B$32/D$5,0) -> 0 | E39: =IF(E$2=$A39,E$3*AtomicWeights!$B$32/E$5,0) -> 0 | F39: =IF(F$2=$A39,F$3*AtomicWeights!$B$32/F$5,0) -> 0 | G39: =IF(G$2=$A39,G$3*AtomicWeights!$B$32/G$5,0) -> 0 | H39: =IF(H$2=$A39,H$3*AtomicWeights!$B$32/H$5,0) -> 0 | I39: =IF(I$2=$A39,I$3*AtomicWeights!$B$32/I$5,0) -> 0 | J39: =IF(J$2=$A39,J$3*AtomicWeights!$B$32/J$5,0) -> 0 | ... BB39: =IF(BB$2=$A39,BB$3*AtomicWeights!$B$32/BB$5,0) -> 0
A40: Th | B40: =AtomicWeights!$C$33 -> NO | C40: =IF(C$2=$A40,C$3*AtomicWeights!$B$33/C$5,0) -> 0 | D40: =IF(D$2=$A40,D$3*AtomicWeights!$B$33/D$5,0) -> 0 | E40: =IF(E$2=$A40,E$3*AtomicWeights!$B$33/E$5,0) -> 0 | F40: =IF(F$2=$A40,F$3*AtomicWeights!$B$33/F$5,0) -> 0 | G40: =IF(G$2=$A40,G$3*AtomicWeights!$B$33/G$5,0) -> 0 | H40: =IF(H$2=$A40,H$3*AtomicWeights!$B$33/H$5,0) -> 0 | I40: =IF(I$2=$A40,I$3*AtomicWeights!$B$33/I$5,0) -> 0 | J40: =IF(J$2=$A40,J$3*AtomicWeights!$B$33/J$5,0) -> 0 | ... BB40: =IF(BB$2=$A40,BB$3*AtomicWeights!$B$33/BB$5,0) -> 0
A41: U | B41: =AtomicWeights!$C$34 -> NO | C41: =IF(C$2=$A41,C$3*AtomicWeights!$B$34/C$5,0) -> 0 | D41: =IF(D$2=$A41,D$3*AtomicWeights!$B$34/D$5,0) -> 0 | E41: =IF(E$2=$A41,E$3*AtomicWeights!$B$34/E$5,0) -> 0 | F41: =IF(F$2=$A41,F$3*AtomicWeights!$B$34/F$5,0) -> 0 | G41: =IF(G$2=$A41,G$3*AtomicWeights!$B$34/G$5,0) -> 0 | H41: =IF(H$2=$A41,H$3*AtomicWeights!$B$34/H$5,0) -> 0 | I41: =IF(I$2=$A41,I$3*AtomicWeights!$B$34/I$5,0) -> 0 | J41: =IF(J$2=$A41,J$3*AtomicWeights!$B$34/J$5,0) -> 0 | ... BB41: =IF(BB$2=$A41,BB$3*AtomicWeights!$B$34/BB$5,0) -> 0
...

Sheet Oxides_typical
A1: Mineral | B1: Ideal formula | C1: SiO2 | D1: TiO2 | E1: ZrO2 | F1: HfO2 | G1: SnO2 | H1: Al2O3 | I1: Fe2O3 | J1: FeO | K1: MnO | L1: ZnO | M1: Cu2O | N1: MgO | O1: CaO | P1: SrO | Q1: BaO | R1: PbO | S1: Na2O | T1: K2O | U1: Li2O | V1: B2O3 | W1: BeO | X1: Nb2O5 | Y1: Ta2O5 | Z1: WO3 | AA1: P2O5 | AB1: As2O5 | AC1: SO3 | AD1: CO2 | AE1: H2O | AF1: F | AG1: Cl | AH1: S (sulfide) | AI1: ThO2 | AJ1: UO2 | AK1: Sc2O3 | AL1: Y2O3 | AM1: La2O3 | AN1: Ce2O3 | AO1: CeO2 | AP1: Pr2O3 | AQ1: Nd2O3 | AR1: Sm2O3 | AS1: Eu2O3 | AT1: Gd2O3 | AU1: Tb2O3 | AV1: Dy2O3 | AW1: Ho2O3 | AX1: Er2O3 | AY1: Tm2O3 | AZ1: Yb2O3 | BA1: Lu2O3 | BB1: Bi2O3 | BC1: Sum of oxides | BD1: − O≡F,Cl,S | BE1: Total (wt%)
A2: Monazite-(Ce) | B2: (Ce,La,Nd,Th)PO4 | C2: 0.4 | H2: 0.02 | J2: 0 | O2: 1 | P2: 0 | R2: 0.098 | AA2: 27.4 | AC2: 0 | AI2: 11.6 | AJ2: 0.385 | AL2: 0 | AM2: 21.7 | AN2: 28.7 | AP2: 1.84 | AQ2: 6 | AR2: 0.6 | AS2: 0 | AT2: 0.09 | AU2: 0 | AV2: 0.2 | AW2: 0.05 | AX2: 0 | AY2: 0 | AZ2: 0 | BA2: 0 | BC2: =SUM(C2:BB2) -> 100.083 | BD2: =AG2*Factors!AG$6+AF2*Factors!AF$6+AH2*Factors!AH$6 -> 0 | BE2: =BC2+BD2 -> 100.083
A3: Bastnäsite-(Ce) | B3: (Ce,La)(CO3)F | C3: 0 | J3: 0 | O3: 0.3 | P3: 0 | Q3: 0 | AA3: 0 | AD3: 20.07 | AE3: 0 | AF3: 8.67 | AI3: 0.15 | AJ3: 0 | AL3: 0.15 | AM3: 24.52 | AN3: 36.68 | AP3: 3.38 | AQ3: 9.21 | AR3: 0.64 | AS3: 0.08 | AT3: 0.25 | AV3: 0 | BC3: =SUM(C3:BB3) -> 104.1 | BD3: =AG3*Factors!AG$6+AF3*Factors!AF$6+AH3*Factors!AH$6 -> -3.650605 | BE3: =BC3+BD3 -> 100.4494
A4: Xenotime-(Y) | B4: YPO4 | C4: 0.1 | H4: 0 | J4: 0 | O4: 0.07 | R4: 0 | AA4: 33.89 | AI4: 0.38 | AJ4: 0.96 | AL4: 46.49 | AM4: 0 | AN4: 0 | AP4: 0 | AQ4: 0 | AR4: 0 | AS4: 0.04 | AT4: 1.89 | AU4: 0.6 | AV4: 5.15 | AW4: 1.06 | AX4: 3.86 | AY4: 0 | AZ4: 4.1 | BA4: 0.52 | BC4: =SUM(C4:BB4) -> 99.11 | BD4: =AG4*Factors!AG$6+AF4*Factors!AF$6+AH4*Factors!AH$6 -> 0 | BE4: =BC4+BD4 -> 99.11
A5: Parisite-(Ce) | B5: CaCe2(CO3)3F2 | C5: 0 | J5: 0 | O5: 10.7 | P5: 0 | Q5: 0 | S5: 0 | AD5: 24.58 | AF5: 5.34 | AI5: 0 | AJ5: 0 | AL5: 0 | AM5: 15.1 | AN5: 28.87 | AP5: 3 | AQ5: 11.65 | AR5: 1.46 | AS5: 0.2 | AT5: 0 | AV5: 0 | BC5: =SUM(C5:BB5) -> 100.9 | BD5: =AG5*Factors!AG$6+AF5*Factors!AF$6+AH5*Factors!AH$6 -> -2.2484695 | BE5: =BC5+BD5 -> 98.651531
A6: Synchysite-(Ce) | B6: CaCe(CO3)2F | C6: 0.14 | J6: 0 | O6: 18.14 | P6: 0 | AD6: 27.95 | AF6: 5.73 | AI6: 0 | AJ6: 0 | AL6: 0.45 | AM6: 9.96 | AN6: 22.34 | AP6: 2.27 | AQ6: 12.73 | AR6: 1.79 | AS6: 0 | AT6: 1.27 | AV6: 0 | BC6: =SUM(C6:BB6) -> 102.77 | BD6: =AG6*Factors!AG$6+AF6*Factors!AF$6+AH6*Factors!AH$6 -> -2.4126836 | BE6: =BC6+BD6 -> 100.35732
A7: Allanite-(Ce) | B7: CaCe(Al2Fe2+)(Si2O7)(SiO4)O(OH) | C7: 29.79 | D7: 0.02 | H7: 12.75 | I7: 10.64 | J7: 9.02 | K7: 0.85 | N7: 0.64 | O7: 10.1 | S7: 0 | AA7: 0 | AE7: 1.74 | AF7: 0 | AI7: 0 | AJ7: 0 | AL7: 0.04 | AM7: 7.2 | AN7: 12.8 | AP7: 1 | AQ7: 3.1 | AR7: 0.6 | AS7: 0 | AT7: 0.06 | AU7: 0 | AV7: 0 | AW7: 0 | AX7: 0.02 | AY7: 0 | AZ7: 0 | BA7: 0 | BC7: =SUM(C7:BB7) -> 100.37 | BD7: =AG7*Factors!AG$6+AF7*Factors!AF$6+AH7*Factors!AH$6 -> 0 | BE7: =BC7+BD7 -> 100.37
A8: Fluorapatite (REE-bearing) | B8: Ca5(PO4)3F | C8: 0.47 | J8: 0.1 | K8: 0.06 | O8: 53.59 | P8: 0.31 | S8: 0.15 | AA8: 41.09 | AC8: 0.08 | AD8: 0 | AE8: 0.05 | AF8: 3.54 | AG8: 0.14 | AI8: 0 | AJ8: 0 | AL8: 0.16 | AM8: 0.42 | AN8: 0.81 | AP8: 0.1 | AQ8: 0.33 | AR8: 0.07 | AS8: 0 | AT8: 0.05 | AV8: 0.03 | AX8: 0 | AZ8: 0 | BC8: =SUM(C8:BB8) -> 101.55 | BD8: =AG8*Factors!AG$6+AF8*Factors!AF$6+AH8*Factors!AH$6 -> -1.5221502 | BE8: =BC8+BD8 -> 100.02785
A9: Florencite-(Ce) | B9: CeAl3(PO4)2(OH)6 | C9: 0 | H9: 29.6 | I9: 0 | O9: 0.47 | P9: 0 | Q9: 0 | AA9: 27.4 | AC9: 0 | AE9: 10.46 | AF9: 0 | AI9: 0 | AL9: 0 | AM9: 8.68 | AN9: 17.79 | AP9: 0 | AQ9: 3.78 | AR9: 1.48 | AS9: 0 | AT9: 0 | AV9: 0 | BC9: =SUM(C9:BB9) -> 99.66 | BD9: =AG9*Factors!AG$6+AF9*Factors!AF$6+AH9*Factors!AH$6 -> 0 | BE9: =BC9+BD9 -> 99.66
A10: Cerianite-(Ce) | B10: (Ce4+,Th)O2 | C10: 0.3 | E10: 0 | J10: 0.4 | O10: 0.8 | X10: 0 | Y10: 0 | AA10: 0 | AE10: 0.5 | AI10: 4 | AL10: 0.5 | AM10: 1.5 | AO10: 90 | AP10: 0.3 | AQ10: 1.5 | AZ10: 0 | BC10: =SUM(C10:BB10) -> 99.8 | BD10: =AG10*Factors!AG$6+AF10*Factors!AF$6+AH10*Factors!AH$6 -> 0 | BE10: =BC10+BD10 -> 99.8
A11: Pyrochlore (REE-bearing, carbonatite) | B11: (Na,Ca)2Nb2O6(OH,F) | C11: 0 | D11: 3.63 | E11: 3.24 | H11: 0 | J11: 1.14 | K11: 0.09 | N11: 0.01 | O11: 16.7 | P11: 0.34 | Q11: 0 | R11: 0.24 | S11: 5.22 | T11: 0 | X11: 60.6 | Y11: 0.06 | AE11: 0 | AF11: 3.8 | AI11: 1.08 | AJ11: 0.1 | AL11: 0.24 | AM11: 0.6 | AN11: 1.85 | AP11: 0.17 | AQ11: 0.58 | AR11: 0.1 | BC11: =SUM(C11:BB11) -> 99.79 | BD11: =AG11*Factors!AG$6+AF11*Factors!AF$6+AH11*Factors!AH$6 -> -1.6000345 | BE11: =BC11+BD11 -> 98.189966
A12: Ancylite-(Ce) | B12: SrCe(CO3)2(OH)·H2O | J12: 0.19 | O12: 1.35 | P12: 23.97 | Q12: 0 | AD12: 23.44 | AE12: 7.06 | AF12: 0 | AI12: 0.53 | AL12: 0 | AM12: 13.08 | AN12: 23.4 | AP12: 1.94 | AQ12: 5.35 | AR12: 0.29 | AT12: 0.14 | BC12: =SUM(C12:BB12) -> 100.74 | BD12: =AG12*Factors!AG$6+AF12*Factors!AF$6+AH12*Factors!AH$6 -> 0 | BE12: =BC12+BD12 -> 100.74
A13: Ion-adsorption REE clay ore (HREE type) | B13: Quartz + kaolinite/halloysite + residual K-feldspar/mica, REE3+ adsorbed on clays | C13: 60.8 | D13: 0.06 | H13: 24.3 | I13: 0.76 | K13: 0.12 | N13: 0.05 | O13: 0.06 | S13: 0.14 | T13: 5.82 | AA13: 0.01 | AE13: 7.5 | AL13: 0.098 | AM13: 0.0027 | AN13: 0.0006 | AP13: 0.001 | AQ13: 0.0045 | AR13: 0.0042 | AS13: 0.00015 | AT13: 0.0104 | AU13: 0.002 | AV13: 0.0101 | AW13: 0.0024 | AX13: 0.0074 | AY13: 0.0011 | AZ13: 0.0038 | BA13: 0.0006 | BC13: =SUM(C13:BB13) -> 99.76895 | BD13: =AG13*Factors!AG$6+AF13*Factors!AF$6+AH13*Factors!AH$6 -> 0 | BE13: =BC13+BD13 -> 99.76895
A14: Britholite-(Ce) | B14: (Ce,Ca)5(SiO4,PO4)3(OH,F) | C14: 19.1 | H14: 0 | J14: 0.18 | K14: 0 | O14: 14.62 | P14: 0.4 | S14: 0.2 | AA14: 4.51 | AE14: 0.46 | AF14: 1.45 | AG14: 0 | AI14: 3.36 | AJ14: 0.17 | AL14: 1.15 | AM14: 12.84 | AN14: 27.55 | AP14: 2.52 | AQ14: 9.63 | AR14: 1.33 | AS14: 0 | AT14: 0.92 | AV14: 0.24 | AX14: 0 | AZ14: 0 | BC14: =SUM(C14:BB14) -> 100.63 | BD14: =AG14*Factors!AG$6+AF14*Factors!AF$6+AH14*Factors!AH$6 -> -0.61053947 | BE14: =BC14+BD14 -> 100.01946
A15: Churchite-(Y) | B15: YPO4·2H2O | C15: 0 | H15: 0 | I15: 0 | O15: 0.73 | AA15: 30.59 | AE15: 15.53 | AL15: 37.96 | AM15: 0.35 | AN15: 0.71 | AP15: 0 | AQ15: 1.45 | AR15: 0.75 | AS15: 0.15 | AT15: 2.34 | AU15: 0.39 | AV15: 3.22 | AW15: 0.81 | AX15: 2.47 | AY15: 0.42 | AZ15: 1.7 | BA15: 0.43 | BC15: =SUM(C15:BB15) -> 100 | BD15: =AG15*Factors!AG$6+AF15*Factors!AF$6+AH15*Factors!AH$6 -> 0 | BE15: =BC15+BD15 -> 100
A16: Rhabdophane-(Ce) | B16: (Ce,La)PO4·H2O | C16: 0 | H16: 0 | I16: 0 | O16: 0.78 | P16: 0 | R16: 0 | AA16: 28.04 | AE16: 7.12 | AI16: 3.65 | AJ16: 0 | AL16: 0.45 | AM16: 14.16 | AN16: 30.48 | AP16: 3.26 | AQ16: 9.97 | AR16: 1.38 | AS16: 0 | AT16: 0.72 | AU16: 0 | AV16: 0 | AW16: 0 | AX16: 0 | AY16: 0 | AZ16: 0 | BA16: 0 | BC16: =SUM(C16:BB16) -> 100.01 | BD16: =AG16*Factors!AG$6+AF16*Factors!AF$6+AH16*Factors!AH$6 -> 0 | BE16: =BC16+BD16 -> 100.01
A17: Fluocerite-(Ce) | B17: CeF3 | C17: 0 | I17: 0 | O17: 0 | AF17: 28.92 | AI17: 0 | AL17: 0 | AM17: 23.14 | AN17: 45.8 | AP17: 3.77 | AQ17: 9.39 | AR17: 0.88 | AS17: 0 | AT17: 0.28 | BC17: =SUM(C17:BB17) -> 112.18 | BD17: =AG17*Factors!AG$6+AF17*Factors!AF$6+AH17*Factors!AH$6 -> -12.177104 | BE17: =BC17+BD17 -> 100.0029
A18: Cerite-(Ce) | B18: (Ce,La,Ca)9(Mg,Fe3+)(SiO4)3(SiO3OH)4(OH)3 | C18: 22.24 | D18: 0.08 | H18: 1.14 | I18: 0.92 | K18: 0.2 | N18: 1.9 | O18: 4.48 | P18: 0 | Q18: 0.45 | S18: 0.24 | T18: 0.16 | AA18: 0 | AC18: 0.14 | AE18: 2.89 | AF18: 0.07 | AI18: 0 | AL18: 0 | AM18: 20.31 | AN18: 35.05 | AP18: 2.46 | AQ18: 6.73 | AR18: 0.54 | AS18: 0 | AT18: 0 | AU18: 0 | AV18: 0 | AX18: 0 | AZ18: 0 | BC18: =SUM(C18:BB18) -> 100 | BD18: =AG18*Factors!AG$6+AF18*Factors!AF$6+AH18*Factors!AH$6 -> -0.029474319 | BE18: =BC18+BD18 -> 99.970526
A19: Eudialyte (REE-bearing) | B19: Na15Ca6(Fe2+,Mn2+)3Zr3Si(Si25O73)(O,OH,H2O)3(Cl,OH)2 | C19: 49.95 | D19: 0.6 | E19: 13.53 | F19: 0.29 | H19: 0 | I19: 0 | J19: 3.89 | K19: 1.99 | N19: 0 | O19: 7.3 | P19: 1.35 | Q19: 0.11 | S19: 16.18 | T19: 0.38 | X19: 0.75 | AC19: 0.26 | AE19: 1 | AF19: 0 | AG19: 1.4 | AI19: 0 | AJ19: 0 | AL19: 0.63 | AM19: 0.34 | AN19: 0.57 | AP19: 0.15 | AQ19: 0.37 | AR19: 0.092 | AS19: 0.026 | AT19: 0.078 | AU19: 0.02 | AV19: 0.103 | AW19: 0.021 | AX19: 0.055 | AY19: 0.008 | AZ19: 0.05 | BA19: 0.006 | BC19: =SUM(C19:BB19) -> 101.499 | BD19: =AG19*Factors!AG$6+AF19*Factors!AF$6+AH19*Factors!AH$6 -> -0.31591819 | BE19: =BC19+BD19 -> 101.18308
A20: Gadolinite-(Y) | B20: Y2Fe2+Be2Si2O10 | C20: 23.36 | I20: 0 | J20: 12.08 | K20: 0 | N20: 0 | O20: 0.03 | S20: 0 | W20: 9.71 | AE20: 0.46 | AI20: 0 | AJ20: 0 | AL20: 28.55 | AM20: 0.21 | AN20: 2.54 | AP20: 1.2 | AQ20: 4.55 | AR20: 2.82 | AS20: 0.6 | AT20: 2.93 | AU20: 1.1 | AV20: 4.06 | AW20: 1.98 | AX20: 1.54 | AY20: 0.2 | AZ20: 0.58 | BA20: 0 | BC20: =SUM(C20:BB20) -> 98.5 | BD20: =AG20*Factors!AG$6+AF20*Factors!AF$6+AH20*Factors!AH$6 -> 0 | BE20: =BC20+BD20 -> 98.5
A21: Zircon (HREE-bearing) | B21: ZrSiO4 (+ xenotime-type (Y,HREE)3+ + P5+ = Zr4+ + Si4+) | C21: 26.49 | E21: 49.81 | F21: 1.83 | H21: 0.11 | J21: 0.01 | K21: 0.03 | O21: 0.4 | R21: 0.87 | S21: 0 | X21: 0 | AA21: 5.46 | AB21: 0.05 | AE21: 0 | AF21: 0.28 | AI21: 0.92 | AJ21: 3.09 | AK21: 0.42 | AL21: 5.47 | AM21: 0.02 | AN21: 0.36 | AP21: 0.02 | AQ21: 0.02 | AR21: 0.11 | AS21: 0 | AT21: 0.35 | AU21: 0 | AV21: 0.81 | AW21: 0 | AX21: 0.5 | AY21: 0 | AZ21: 0.78 | BA21: 0 | BB21: 0.12 | BC21: =SUM(C21:BB21) -> 98.33 | BD21: =AG21*Factors!AG$6+AF21*Factors!AF$6+AH21*Factors!AH$6 -> -0.11789728 | BE21: =BC21+BD21 -> 98.212103
A22: Aeschynite-(Ce) | B22: (Ce,Ca,Fe,Th)(Ti,Nb)2(O,OH)6 | C22: 0.14 | D22: 32.54 | E22: 1.9 | G22: 0 | I22: 6.22 | J22: 0 | K22: 0 | O22: 1.55 | X22: 10.85 | Y22: 0.08 | AE22: 2.64 | AF22: 0.34 | AI22: 0 | AJ22: 0 | AL22: 2.9 | AM22: 5.4 | AN22: 16.94 | AP22: 2.27 | AQ22: 8.83 | AR22: 1.86 | AS22: 1.27 | AT22: 1.75 | AV22: 0.84 | AX22: 0 | AZ22: 0 | BC22: =SUM(C22:BB22) -> 98.32 | BD22: =AG22*Factors!AG$6+AF22*Factors!AF$6+AH22*Factors!AH$6 -> -0.14316098 | BE22: =BC22+BD22 -> 98.176839
A23: Euxenite-(Y) | B23: (Y,Ca,Ce,U,Th)(Nb,Ta,Ti)2O6 | C23: 0 | D23: 20.7 | E23: 0 | G23: 0.14 | H23: 0 | I23: 0 | J23: 0.23 | K23: 0.23 | N23: 0 | O23: 1.09 | R23: 0 | S23: 0 | T23: 0 | X23: 32.09 | Y23: 10.05 | Z23: 0.1 | AE23: 0 | AI23: 0.65 | AJ23: 4.47 | AK23: 0.05 | AL23: 19.89 | AM23: 0 | AN23: 0.12 | AP23: 0 | AQ23: 0.47 | AR23: 1.02 | AS23: 0.47 | AT23: 1.68 | AU23: 0.36 | AV23: 1.93 | AW23: 0.42 | AX23: 1.01 | AY23: 0.39 | AZ23: 1.07 | BA23: 0.16 | BC23: =SUM(C23:BB23) -> 98.79 | BD23: =AG23*Factors!AG$6+AF23*Factors!AF$6+AH23*Factors!AH$6 -> 0 | BE23: =BC23+BD23 -> 98.79
A24: Fergusonite-(Y) | B24: YNbO4 | C24: 0 | D24: 0.97 | G24: 0 | J24: 0 | O24: 0.82 | X24: 44.42 | Y24: 0 | Z24: 0 | AE24: 0 | AI24: 4.06 | AJ24: 2.39 | AL24: 27.49 | AM24: 0.11 | AN24: 0.94 | AP24: 0.15 | AQ24: 1.82 | AR24: 1.17 | AS24: 0.03 | AT24: 2.21 | AU24: 0.55 | AV24: 4.59 | AW24: 1.02 | AX24: 3.21 | AY24: 0.59 | AZ24: 3.53 | BA24: 0.1 | BC24: =SUM(C24:BB24) -> 100.17 | BD24: =AG24*Factors!AG$6+AF24*Factors!AF$6+AH24*Factors!AH$6 -> 0 | BE24: =BC24+BD24 -> 100.17
A25: Loparite-(Ce) | B25: (Na,Ce,Sr)(Ce,Th)(Ti,Nb)2O6 | C25: 0 | D25: 39.47 | E25: 0 | H25: 0 | I25: 0 | J25: 0.18 | O25: 4.47 | P25: 3.4 | S25: 7.45 | T25: 0 | X25: 9.46 | Y25: 0.63 | AF25: 0 | AI25: 0.81 | AJ25: 0 | AM25: 8.78 | AN25: 17.61 | AP25: 1.63 | AQ25: 5.05 | AR25: 0 | BC25: =SUM(C25:BB25) -> 98.94 | BD25: =AG25*Factors!AG$6+AF25*Factors!AF$6+AH25*Factors!AH$6 -> 0 | BE25: =BC25+BD25 -> 98.94
A26: Samarskite-(Y) | B26: YFe3+Nb2O8 | C26: 0 | D26: 4.05 | E26: 0 | G26: 1.05 | H26: 0 | I26: 6.06 | J26: 3.86 | K26: 1.15 | N26: 0.1 | O26: 0.28 | R26: 0 | S26: 0 | T26: 0 | X26: 36.03 | Y26: 13.13 | Z26: 1.81 | AE26: 0 | AI26: 1.59 | AJ26: 15.81 | AK26: 0.66 | AL26: 8.95 | AM26: 0 | AN26: 0 | AP26: 0 | AQ26: 1.12 | AR26: 0.67 | AS26: 0 | AT26: 0.98 | AU26: 0 | AV26: 0.96 | AW26: 0 | AX26: 0 | AY26: 0 | AZ26: 1.07 | BA26: 0 | BC26: =SUM(C26:BB26) -> 99.33 | BD26: =AG26*Factors!AG$6+AF26*Factors!AF$6+AH26*Factors!AH$6 -> 0 | BE26: =BC26+BD26 -> 99.33
A27: Albite | B27: NaAlSi3O8 | C27: 68.71 | H27: 19.63 | O27: 0.22 | S27: 11.72 | T27: 0.03 | BC27: =SUM(C27:BB27) -> 100.31 | BD27: =AG27*Factors!AG$6+AF27*Factors!AF$6+AH27*Factors!AH$6 -> 0 | BE27: =BC27+BD27 -> 100.31
A28: Zircon | B28: ZrSiO4 | C28: 32.86 | E28: 66.72 | F28: 1.15 | AI28: 0.01 | AJ28: 0.03 | BC28: =SUM(C28:BB28) -> 100.77 | BD28: =AG28*Factors!AG$6+AF28*Factors!AF$6+AH28*Factors!AH$6 -> 0 | BE28: =BC28+BD28 -> 100.77
A29: Muscovite | B29: KAl2(Si3Al)O10(OH)2 | C29: 45.87 | H29: 38.69 | N29: 0.1 | S29: 0.64 | T29: 10.08 | AE29: 4.67 | BC29: =SUM(C29:BB29) -> 100.05 | BD29: =AG29*Factors!AG$6+AF29*Factors!AF$6+AH29*Factors!AH$6 -> 0 | BE29: =BC29+BD29 -> 100.05
A30: Quartz | B30: SiO2 | C30: 100 | BC30: =SUM(C30:BB30) -> 100 | BD30: =AG30*Factors!AG$6+AF30*Factors!AF$6+AH30*Factors!AH$6 -> 0 | BE30: =BC30+BD30 -> 100
A31: Aegirine | B31: NaFe3+Si2O6 | C31: 51.35 | D31: 1.1 | H31: 2.15 | I31: 28.66 | J31: 2.24 | N31: 0.1 | O31: 1.25 | S31: 12.66 | T31: 0.15 | AE31: 0.29 | BC31: =SUM(C31:BB31) -> 99.95 | BD31: =AG31*Factors!AG$6+AF31*Factors!AF$6+AH31*Factors!AH$6 -> 0 | BE31: =BC31+BD31 -> 99.95
A32: Pachnolite | B32: NaCaAlF6·H2O | H32: 22.96 | O32: 25.26 | S32: 13.95 | AE32: 8.11 | AF32: 51.34 | BC32: =SUM(C32:BB32) -> 121.62 | BD32: =AG32*Factors!AG$6+AF32*Factors!AF$6+AH32*Factors!AH$6 -> -21.617308 | BE32: =BC32+BD32 -> 100.00269
A33: Orthoclase | B33: KAlSi3O8 | C33: 65.39 | H33: 18.45 | Q33: 0.02 | S33: 1.08 | T33: 14.76 | BC33: =SUM(C33:BB33) -> 99.7 | BD33: =AG33*Factors!AG$6+AF33*Factors!AF$6+AH33*Factors!AH$6 -> 0 | BE33: =BC33+BD33 -> 99.7
A34: Hematite | B34: α-Fe2O3 | I34: 98.14 | J34: 1.29 | K34: 0.87 | BC34: =SUM(C34:BB34) -> 100.3 | BD34: =AG34*Factors!AG$6+AF34*Factors!AF$6+AH34*Factors!AH$6 -> 0 | BE34: =BC34+BD34 -> 100.3
A35: Magnetite | B35: Fe2+Fe3+2O4 | C35: 0.27 | H35: 0.21 | I35: 68.85 | J35: 30.78 | BC35: =SUM(C35:BB35) -> 100.11 | BD35: =AG35*Factors!AG$6+AF35*Factors!AF$6+AH35*Factors!AH$6 -> 0 | BE35: =BC35+BD35 -> 100.11
A36: Thorite | B36: (Th,U)SiO4 | C36: 16.47 | D36: 0.1 | H36: 1.29 | J36: 0.59 | N36: 0.01 | R36: 0.1 | AE36: 0.86 | AI36: 71.61 | AJ36: 8.36 | AN36: 0.54 | BC36: =SUM(C36:BB36) -> 99.93 | BD36: =AG36*Factors!AG$6+AF36*Factors!AF$6+AH36*Factors!AH$6 -> 0 | BE36: =BC36+BD36 -> 99.93
A37: Cryolite | B37: Na3AlF6 | H37: 24.58 | S37: 43.69 | AF37: 54.28 | BC37: =SUM(C37:BB37) -> 122.55 | BD37: =AG37*Factors!AG$6+AF37*Factors!AF$6+AH37*Factors!AH$6 -> -22.855229 | BE37: =BC37+BD37 -> 99.694771
A38: Cassiterite | B38: SnO2 | C38: 0.18 | D38: 0.01 | G38: 99.26 | J38: 0.11 | X38: 0.03 | Y38: 0.01 | Z38: 0.01 | BC38: =SUM(C38:BB38) -> 99.61 | BD38: =AG38*Factors!AG$6+AF38*Factors!AF$6+AH38*Factors!AH$6 -> 0 | BE38: =BC38+BD38 -> 99.61
A39: Nepheline | B39: (Na,K)AlSiO4 | C39: 43.55 | H39: 34.66 | N39: 0.05 | O39: 4.44 | S39: 12.09 | T39: 4.87 | AE39: 0.5 | BC39: =SUM(C39:BB39) -> 100.16 | BD39: =AG39*Factors!AG$6+AF39*Factors!AF$6+AH39*Factors!AH$6 -> 0 | BE39: =BC39+BD39 -> 100.16
A40: Hendricksite (Zn-mica) | B40: K(Zn,Mn)3Si3AlO10(OH)2 | C40: 31.58 | D40: 0.32 | H40: 13.72 | I40: 2.25 | J40: 0.34 | K40: 12.28 | L40: 22.97 | N40: 3.69 | O40: 0.02 | Q40: 0.65 | S40: 0.24 | T40: 7.91 | AE40: 3.95 | BC40: =SUM(C40:BB40) -> 99.92 | BD40: =AG40*Factors!AG$6+AF40*Factors!AF$6+AH40*Factors!AH$6 -> 0 | BE40: =BC40+BD40 -> 99.92
...

Sheet Oxides_min
A1: Mineral | B1: Ideal formula | C1: SiO2 | D1: TiO2 | E1: ZrO2 | F1: HfO2 | G1: SnO2 | H1: Al2O3 | I1: Fe2O3 | J1: FeO | K1: MnO | L1: ZnO | M1: Cu2O | N1: MgO | O1: CaO | P1: SrO | Q1: BaO | R1: PbO | S1: Na2O | T1: K2O | U1: Li2O | V1: B2O3 | W1: BeO | X1: Nb2O5 | Y1: Ta2O5 | Z1: WO3 | AA1: P2O5 | AB1: As2O5 | AC1: SO3 | AD1: CO2 | AE1: H2O | AF1: F | AG1: Cl | AH1: S (sulfide) | AI1: ThO2 | AJ1: UO2 | AK1: Sc2O3 | AL1: Y2O3 | AM1: La2O3 | AN1: Ce2O3 | AO1: CeO2 | AP1: Pr2O3 | AQ1: Nd2O3 | AR1: Sm2O3 | AS1: Eu2O3 | AT1: Gd2O3 | AU1: Tb2O3 | AV1: Dy2O3 | AW1: Ho2O3 | AX1: Er2O3 | AY1: Tm2O3 | AZ1: Yb2O3 | BA1: Lu2O3 | BB1: Bi2O3 | BC1: Sum of oxides | BD1: − O≡F,Cl,S | BE1: Total (wt%)
A2: Monazite-(Ce) | B2: (Ce,La,Nd,Th)PO4 | C2: 0.05 | H2: 0 | J2: 0 | O2: 0.1 | P2: 0 | R2: 0.01 | AA2: 25 | AC2: 0 | AI2: 1 | AJ2: 0 | AL2: 0 | AM2: 10 | AN2: 25 | AP2: 1 | AQ2: 6 | AR2: 0.2 | AS2: 0 | AT2: 0.05 | AU2: 0 | AV2: 0 | AW2: 0 | AX2: 0 | AY2: 0 | AZ2: 0 | BA2: 0 | BC2: =SUM(C2:BB2) -> 68.41 | BD2: =AG2*Factors!AG$6+AF2*Factors!AF$6+AH2*Factors!AH$6 -> 0 | BE2: =BC2+BD2 -> 68.41
A3: Bastnäsite-(Ce) | B3: (Ce,La)(CO3)F | C3: 0 | J3: 0 | O3: 0 | P3: 0 | Q3: 0 | AA3: 0 | AD3: 18.5 | AE3: 0 | AF3: 5.5 | AI3: 0 | AJ3: 0 | AL3: 0 | AM3: 14 | AN3: 28 | AP3: 1.5 | AQ3: 3 | AR3: 0.1 | AS3: 0 | AT3: 0 | AV3: 0 | BC3: =SUM(C3:BB3) -> 70.6 | BD3: =AG3*Factors!AG$6+AF3*Factors!AF$6+AH3*Factors!AH$6 -> -2.3158394 | BE3: =BC3+BD3 -> 68.284161
A4: Xenotime-(Y) | B4: YPO4 | C4: 0 | H4: 0 | J4: 0 | O4: 0 | R4: 0 | AA4: 32 | AI4: 0 | AJ4: 0 | AL4: 38 | AM4: 0 | AN4: 0 | AP4: 0 | AQ4: 0 | AR4: 0.05 | AS4: 0 | AT4: 0.8 | AU4: 0.2 | AV4: 3 | AW4: 0.6 | AX4: 2.5 | AY4: 0.3 | AZ4: 2 | BA4: 0.2 | BC4: =SUM(C4:BB4) -> 79.65 | BD4: =AG4*Factors!AG$6+AF4*Factors!AF$6+AH4*Factors!AH$6 -> 0 | BE4: =BC4+BD4 -> 79.65
A5: Parisite-(Ce) | B5: CaCe2(CO3)3F2 | C5: 0 | J5: 0 | O5: 9 | P5: 0 | Q5: 0 | S5: 0 | AD5: 23 | AF5: 5 | AI5: 0 | AJ5: 0 | AL5: 0 | AM5: 9 | AN5: 24 | AP5: 1.5 | AQ5: 5 | AR5: 0.3 | AS5: 0 | AT5: 0 | AV5: 0 | BC5: =SUM(C5:BB5) -> 76.8 | BD5: =AG5*Factors!AG$6+AF5*Factors!AF$6+AH5*Factors!AH$6 -> -2.1053085 | BE5: =BC5+BD5 -> 74.694691
A6: Synchysite-(Ce) | B6: CaCe(CO3)2F | C6: 0 | J6: 0 | O6: 15.5 | P6: 0 | AD6: 26 | AF6: 4 | AI6: 0 | AJ6: 0 | AL6: 0 | AM6: 6 | AN6: 18 | AP6: 1 | AQ6: 4 | AR6: 0.2 | AS6: 0 | AT6: 0 | AV6: 0 | BC6: =SUM(C6:BB6) -> 74.7 | BD6: =AG6*Factors!AG$6+AF6*Factors!AF$6+AH6*Factors!AH$6 -> -1.6842468 | BE6: =BC6+BD6 -> 73.015753
A7: Allanite-(Ce) | B7: CaCe(Al2Fe2+)(Si2O7)(SiO4)O(OH) | C7: 29 | D7: 0 | H7: 10 | I7: 1 | J7: 3 | K7: 0.05 | N7: 0 | O7: 8 | S7: 0 | AA7: 0 | AE7: 1.2 | AF7: 0 | AI7: 0 | AJ7: 0 | AL7: 0 | AM7: 2 | AN7: 8 | AP7: 0.5 | AQ7: 1.5 | AR7: 0.1 | AS7: 0 | AT7: 0 | AU7: 0 | AV7: 0 | AW7: 0 | AX7: 0 | AY7: 0 | AZ7: 0 | BA7: 0 | BC7: =SUM(C7:BB7) -> 64.35 | BD7: =AG7*Factors!AG$6+AF7*Factors!AF$6+AH7*Factors!AH$6 -> 0 | BE7: =BC7+BD7 -> 64.35
A8: Fluorapatite (REE-bearing) | B8: Ca5(PO4)3F | C8: 0 | J8: 0 | K8: 0 | O8: 51 | P8: 0 | S8: 0 | AA8: 38 | AC8: 0 | AD8: 0 | AE8: 0 | AF8: 2.5 | AG8: 0 | AI8: 0 | AJ8: 0 | AL8: 0 | AM8: 0.1 | AN8: 0.3 | AP8: 0 | AQ8: 0.1 | AR8: 0 | AS8: 0 | AT8: 0 | AV8: 0 | AX8: 0 | AZ8: 0 | BC8: =SUM(C8:BB8) -> 92 | BD8: =AG8*Factors!AG$6+AF8*Factors!AF$6+AH8*Factors!AH$6 -> -1.0526543 | BE8: =BC8+BD8 -> 90.947346
A9: Florencite-(Ce) | B9: CeAl3(PO4)2(OH)6 | C9: 0 | H9: 27 | I9: 0 | O9: 0.2 | P9: 0 | Q9: 0 | AA9: 24 | AC9: 0 | AE9: 10 | AF9: 0 | AI9: 0 | AL9: 0 | AM9: 3 | AN9: 8 | AP9: 0.5 | AQ9: 2 | AR9: 0 | AS9: 0 | AT9: 0 | AV9: 0 | BC9: =SUM(C9:BB9) -> 74.7 | BD9: =AG9*Factors!AG$6+AF9*Factors!AF$6+AH9*Factors!AH$6 -> 0 | BE9: =BC9+BD9 -> 74.7
A10: Cerianite-(Ce) | B10: (Ce4+,Th)O2 | C10: 0 | E10: 0 | J10: 0 | O10: 0 | X10: 0 | Y10: 0 | AA10: 0 | AE10: 0 | AI10: 0 | AL10: 0 | AM10: 0 | AO10: 78 | AP10: 0 | AQ10: 0 | AZ10: 0 | BC10: =SUM(C10:BB10) -> 78 | BD10: =AG10*Factors!AG$6+AF10*Factors!AF$6+AH10*Factors!AH$6 -> 0 | BE10: =BC10+BD10 -> 78
A11: Pyrochlore (REE-bearing, carbonatite) | B11: (Na,Ca)2Nb2O6(OH,F) | C11: 0 | D11: 1 | E11: 0 | H11: 0 | J11: 0 | K11: 0 | N11: 0 | O11: 10 | P11: 0 | Q11: 0 | R11: 0 | S11: 1 | T11: 0 | X11: 45 | Y11: 0 | AE11: 0 | AF11: 1.2 | AI11: 0 | AJ11: 0 | AL11: 0 | AM11: 0 | AN11: 0.5 | AP11: 0 | AQ11: 0 | AR11: 0 | BC11: =SUM(C11:BB11) -> 58.7 | BD11: =AG11*Factors!AG$6+AF11*Factors!AF$6+AH11*Factors!AH$6 -> -0.50527404 | BE11: =BC11+BD11 -> 58.194726
A12: Ancylite-(Ce) | B12: SrCe(CO3)2(OH)·H2O | J12: 0 | O12: 0 | P12: 17 | Q12: 0 | AD12: 22 | AE12: 5.5 | AF12: 0 | AI12: 0 | AL12: 0 | AM12: 8 | AN12: 18 | AP12: 1 | AQ12: 3 | AR12: 0 | AT12: 0 | BC12: =SUM(C12:BB12) -> 74.5 | BD12: =AG12*Factors!AG$6+AF12*Factors!AF$6+AH12*Factors!AH$6 -> 0 | BE12: =BC12+BD12 -> 74.5
A13: Ion-adsorption REE clay ore (HREE type) | B13: Quartz + kaolinite/halloysite + residual K-feldspar/mica, REE3+ adsorbed on clays | C13: 45 | D13: 0.03 | H13: 13 | I13: 0.5 | K13: 0.02 | N13: 0.03 | O13: 0.03 | S13: 0.03 | T13: 0.5 | AA13: 0.01 | AE13: 3 | AL13: 0.005 | AM13: 0.0009 | AN13: 0.0002 | AP13: 0.0003 | AQ13: 0.0015 | AR13: 0.001 | AS13: 5e-05 | AT13: 0.0015 | AU13: 0 | AV13: 0 | AW13: 0 | AX13: 0 | AY13: 0 | AZ13: 0.0002 | BA13: 5e-05 | BC13: =SUM(C13:BB13) -> 62.1607 | BD13: =AG13*Factors!AG$6+AF13*Factors!AF$6+AH13*Factors!AH$6 -> 0 | BE13: =BC13+BD13 -> 62.1607
A14: Britholite-(Ce) | B14: (Ce,Ca)5(SiO4,PO4)3(OH,F) | C14: 12 | H14: 0 | J14: 0 | K14: 0 | O14: 10 | P14: 0 | S14: 0 | AA14: 2 | AE14: 0 | AF14: 0.5 | AG14: 0 | AI14: 0.5 | AJ14: 0 | AL14: 0 | AM14: 5 | AN14: 17 | AP14: 1 | AQ14: 4 | AR14: 0.3 | AS14: 0 | AT14: 0.2 | AV14: 0 | AX14: 0 | AZ14: 0 | BC14: =SUM(C14:BB14) -> 52.5 | BD14: =AG14*Factors!AG$6+AF14*Factors!AF$6+AH14*Factors!AH$6 -> -0.21053085 | BE14: =BC14+BD14 -> 52.289469
A15: Churchite-(Y) | B15: YPO4·2H2O | C15: 0 | H15: 0 | I15: 0 | O15: 0 | AA15: 29 | AE15: 14 | AL15: 35 | AM15: 0 | AN15: 0 | AP15: 0 | AQ15: 0 | AR15: 0 | AS15: 0 | AT15: 1 | AU15: 0.1 | AV15: 1.5 | AW15: 0.2 | AX15: 1 | AY15: 0 | AZ15: 0.5 | BA15: 0 | BC15: =SUM(C15:BB15) -> 82.3 | BD15: =AG15*Factors!AG$6+AF15*Factors!AF$6+AH15*Factors!AH$6 -> 0 | BE15: =BC15+BD15 -> 82.3
A16: Rhabdophane-(Ce) | B16: (Ce,La)PO4·H2O | C16: 0 | H16: 0 | I16: 0 | O16: 0.2 | P16: 0 | R16: 0 | AA16: 24 | AE16: 5 | AI16: 0 | AJ16: 0 | AL16: 0 | AM16: 8 | AN16: 20 | AP16: 1 | AQ16: 6 | AR16: 0.5 | AS16: 0 | AT16: 0.2 | AU16: 0 | AV16: 0 | AW16: 0 | AX16: 0 | AY16: 0 | AZ16: 0 | BA16: 0 | BC16: =SUM(C16:BB16) -> 64.9 | BD16: =AG16*Factors!AG$6+AF16*Factors!AF$6+AH16*Factors!AH$6 -> 0 | BE16: =BC16+BD16 -> 64.9
A17: Fluocerite-(Ce) | B17: CeF3 | C17: 0 | I17: 0 | O17: 0 | AF17: 24.5 | AI17: 0 | AL17: 0 | AM17: 15 | AN17: 38 | AP17: 2 | AQ17: 3 | AR17: 0.1 | AS17: 0 | AT17: 0 | BC17: =SUM(C17:BB17) -> 82.6 | BD17: =AG17*Factors!AG$6+AF17*Factors!AF$6+AH17*Factors!AH$6 -> -10.316012 | BE17: =BC17+BD17 -> 72.283988
A18: Cerite-(Ce) | B18: (Ce,La,Ca)9(Mg,Fe3+)(SiO4)3(SiO3OH)4(OH)3 | C18: 20 | D18: 0 | H18: 0 | I18: 0.5 | K18: 0 | N18: 0.3 | O18: 1.5 | P18: 0 | Q18: 0 | S18: 0 | T18: 0 | AA18: 0 | AC18: 0 | AE18: 2.5 | AF18: 0 | AI18: 0 | AL18: 0 | AM18: 10 | AN18: 23 | AP18: 0.5 | AQ18: 1.5 | AR18: 0.1 | AS18: 0 | AT18: 0 | AU18: 0 | AV18: 0 | AX18: 0 | AZ18: 0 | BC18: =SUM(C18:BB18) -> 59.9 | BD18: =AG18*Factors!AG$6+AF18*Factors!AF$6+AH18*Factors!AH$6 -> 0 | BE18: =BC18+BD18 -> 59.9
A19: Eudialyte (REE-bearing) | B19: Na15Ca6(Fe2+,Mn2+)3Zr3Si(Si25O73)(O,OH,H2O)3(Cl,OH)2 | C19: 45 | D19: 0.1 | E19: 9 | F19: 0 | H19: 0 | I19: 0 | J19: 0.8 | K19: 0.5 | N19: 0 | O19: 4.5 | P19: 0.1 | Q19: 0 | S19: 11 | T19: 0.2 | X19: 0.1 | AC19: 0 | AE19: 0.3 | AF19: 0 | AG19: 0.2 | AI19: 0 | AJ19: 0 | AL19: 0.2 | AM19: 0.1 | AN19: 0.3 | AP19: 0 | AQ19: 0.2 | AR19: 0 | AS19: 0 | AT19: 0 | AU19: 0 | AV19: 0 | AW19: 0 | AX19: 0 | AY19: 0 | AZ19: 0 | BA19: 0 | BC19: =SUM(C19:BB19) -> 72.6 | BD19: =AG19*Factors!AG$6+AF19*Factors!AF$6+AH19*Factors!AH$6 -> -0.045131171 | BE19: =BC19+BD19 -> 72.554869
A20: Gadolinite-(Y) | B20: Y2Fe2+Be2Si2O10 | C20: 21 | I20: 0 | J20: 7 | K20: 0 | N20: 0 | O20: 0 | S20: 0 | W20: 7 | AE20: 0.3 | AI20: 0 | AJ20: 0 | AL20: 20 | AM20: 0 | AN20: 0.5 | AP20: 0.1 | AQ20: 0.5 | AR20: 0.3 | AS20: 0 | AT20: 0.8 | AU20: 0.1 | AV20: 1 | AW20: 0.2 | AX20: 0.8 | AY20: 0.1 | AZ20: 0.5 | BA20: 0 | BC20: =SUM(C20:BB20) -> 60.2 | BD20: =AG20*Factors!AG$6+AF20*Factors!AF$6+AH20*Factors!AH$6 -> 0 | BE20: =BC20+BD20 -> 60.2
A21: Zircon (HREE-bearing) | B21: ZrSiO4 (+ xenotime-type (Y,HREE)3+ + P5+ = Zr4+ + Si4+) | C21: 22 | E21: 41 | F21: 0.5 | H21: 0 | J21: 0 | K21: 0 | O21: 0 | R21: 0 | S21: 0 | X21: 0 | AA21: 0 | AB21: 0 | AE21: 0 | AF21: 0 | AI21: 0 | AJ21: 0 | AK21: 0 | AL21: 0 | AM21: 0 | AN21: 0 | AP21: 0 | AQ21: 0 | AR21: 0 | AS21: 0 | AT21: 0 | AU21: 0 | AV21: 0 | AW21: 0 | AX21: 0 | AY21: 0 | AZ21: 0 | BA21: 0 | BB21: 0 | BC21: =SUM(C21:BB21) -> 63.5 | BD21: =AG21*Factors!AG$6+AF21*Factors!AF$6+AH21*Factors!AH$6 -> 0 | BE21: =BC21+BD21 -> 63.5
A22: Aeschynite-(Ce) | B22: (Ce,Ca,Fe,Th)(Ti,Nb)2(O,OH)6 | C22: 0 | D22: 19 | E22: 0 | G22: 0 | I22: 0.5 | J22: 0 | K22: 0 | O22: 0.7 | X22: 0.3 | Y22: 0 | AE22: 0 | AF22: 0 | AI22: 0 | AJ22: 0 | AL22: 0 | AM22: 2.6 | AN22: 8 | AP22: 1.4 | AQ22: 4.2 | AR22: 0.4 | AS22: 0 | AT22: 0 | AV22: 0 | AX22: 0 | AZ22: 0 | BC22: =SUM(C22:BB22) -> 37.1 | BD22: =AG22*Factors!AG$6+AF22*Factors!AF$6+AH22*Factors!AH$6 -> 0 | BE22: =BC22+BD22 -> 37.1
A23: Euxenite-(Y) | B23: (Y,Ca,Ce,U,Th)(Nb,Ta,Ti)2O6 | C23: 0 | D23: 16 | E23: 0 | G23: 0 | H23: 0 | I23: 0 | J23: 0 | K23: 0 | N23: 0 | O23: 0.2 | R23: 0 | S23: 0 | T23: 0 | X23: 22 | Y23: 0.5 | Z23: 0 | AE23: 0 | AI23: 0.5 | AJ23: 0.7 | AK23: 0 | AL23: 8.9 | AM23: 0 | AN23: 0.1 | AP23: 0 | AQ23: 0.3 | AR23: 0.6 | AS23: 0.3 | AT23: 1.3 | AU23: 0.25 | AV23: 1.5 | AW23: 0.2 | AX23: 0.7 | AY23: 0.1 | AZ23: 0.4 | BA23: 0.1 | BC23: =SUM(C23:BB23) -> 54.65 | BD23: =AG23*Factors!AG$6+AF23*Factors!AF$6+AH23*Factors!AH$6 -> 0 | BE23: =BC23+BD23 -> 54.65
A24: Fergusonite-(Y) | B24: YNbO4 | C24: 0 | D24: 0.5 | G24: 0 | J24: 0 | O24: 0.5 | X24: 39.5 | Y24: 0 | Z24: 0 | AE24: 0 | AI24: 0.2 | AJ24: 0.06 | AL24: 20.4 | AM24: 0 | AN24: 0.5 | AP24: 0.06 | AQ24: 1.4 | AR24: 0.9 | AS24: 0 | AT24: 1.8 | AU24: 0.4 | AV24: 3.6 | AW24: 0.8 | AX24: 1.4 | AY24: 0.2 | AZ24: 2.1 | BA24: 0 | BC24: =SUM(C24:BB24) -> 74.32 | BD24: =AG24*Factors!AG$6+AF24*Factors!AF$6+AH24*Factors!AH$6 -> 0 | BE24: =BC24+BD24 -> 74.32
A25: Loparite-(Ce) | B25: (Na,Ce,Sr)(Ce,Th)(Ti,Nb)2O6 | C25: 0 | D25: 35 | E25: 0 | H25: 0 | I25: 0 | J25: 0 | O25: 0.6 | P25: 0.9 | S25: 7.3 | T25: 0 | X25: 3.3 | Y25: 0 | AF25: 0 | AI25: 0.1 | AJ25: 0 | AM25: 7.4 | AN25: 15.2 | AP25: 1 | AQ25: 2.9 | AR25: 0 | BC25: =SUM(C25:BB25) -> 73.7 | BD25: =AG25*Factors!AG$6+AF25*Factors!AF$6+AH25*Factors!AH$6 -> 0 | BE25: =BC25+BD25 -> 73.7
A26: Samarskite-(Y) | B26: YFe3+Nb2O8 | C26: 0 | D26: 0.2 | E26: 0 | G26: 0 | H26: 0 | I26: 0 | J26: 3 | K26: 0.4 | N26: 0 | O26: 0.07 | R26: 0 | S26: 0 | T26: 0 | X26: 22 | Y26: 1 | Z26: 0.5 | AE26: 0 | AI26: 0.5 | AJ26: 2.5 | AK26: 0 | AL26: 3.9 | AM26: 0 | AN26: 0 | AP26: 0 | AQ26: 0.26 | AR26: 0.5 | AS26: 0 | AT26: 0.9 | AU26: 0 | AV26: 0.5 | AW26: 0 | AX26: 0 | AY26: 0 | AZ26: 0.5 | BA26: 0 | BC26: =SUM(C26:BB26) -> 36.73 | BD26: =AG26*Factors!AG$6+AF26*Factors!AF$6+AH26*Factors!AH$6 -> 0 | BE26: =BC26+BD26 -> 36.73
A27: Albite | B27: NaAlSi3O8 | C27: 66.04 | H27: 19.44 | O27: 0 | S27: 10.57 | T27: 0 | BC27: =SUM(C27:BB27) -> 96.05 | BD27: =AG27*Factors!AG$6+AF27*Factors!AF$6+AH27*Factors!AH$6 -> 0 | BE27: =BC27+BD27 -> 96.05
A28: Zircon | B28: ZrSiO4 | C28: 32.78 | E28: 66.72 | F28: 0 | AI28: 0 | AJ28: 0 | BC28: =SUM(C28:BB28) -> 99.5 | BD28: =AG28*Factors!AG$6+AF28*Factors!AF$6+AH28*Factors!AH$6 -> 0 | BE28: =BC28+BD28 -> 99.5
A29: Muscovite | B29: KAl2(Si3Al)O10(OH)2 | C29: 45.26 | H29: 38.4 | N29: 0 | S29: 0 | T29: 10.08 | AE29: 4.52 | BC29: =SUM(C29:BB29) -> 98.26 | BD29: =AG29*Factors!AG$6+AF29*Factors!AF$6+AH29*Factors!AH$6 -> 0 | BE29: =BC29+BD29 -> 98.26
A30: Quartz | B30: SiO2 | C30: 100 | BC30: =SUM(C30:BB30) -> 100 | BD30: =AG30*Factors!AG$6+AF30*Factors!AF$6+AH30*Factors!AH$6 -> 0 | BE30: =BC30+BD30 -> 100
A31: Aegirine | B31: NaFe3+Si2O6 | C31: 51.35 | D31: 0 | H31: 0 | I31: 28.66 | J31: 0 | N31: 0 | O31: 0 | S31: 12.66 | T31: 0 | AE31: 0 | BC31: =SUM(C31:BB31) -> 92.67 | BD31: =AG31*Factors!AG$6+AF31*Factors!AF$6+AH31*Factors!AH$6 -> 0 | BE31: =BC31+BD31 -> 92.67
A32: Pachnolite | B32: NaCaAlF6·H2O | H32: 22.96 | O32: 24.09 | S32: 13.95 | AE32: 8.11 | AF32: 50.61 | BC32: =SUM(C32:BB32) -> 119.72 | BD32: =AG32*Factors!AG$6+AF32*Factors!AF$6+AH32*Factors!AH$6 -> -21.309933 | BE32: =BC32+BD32 -> 98.410067
A33: Orthoclase | B33: KAlSi3O8 | C33: 64.76 | H33: 18.32 | Q33: 0 | S33: 0 | T33: 14.76 | BC33: =SUM(C33:BB33) -> 97.84 | BD33: =AG33*Factors!AG$6+AF33*Factors!AF$6+AH33*Factors!AH$6 -> 0 | BE33: =BC33+BD33 -> 97.84
A34: Hematite | B34: α-Fe2O3 | I34: 98.14 | J34: 0 | K34: 0 | BC34: =SUM(C34:BB34) -> 98.14 | BD34: =AG34*Factors!AG$6+AF34*Factors!AF$6+AH34*Factors!AH$6 -> 0 | BE34: =BC34+BD34 -> 98.14
A35: Magnetite | B35: Fe2+Fe3+2O4 | C35: 0 | D35: 0 | H35: 0 | I35: 67.16 | J35: 30.78 | K35: 0 | N35: 0 | BC35: =SUM(C35:BB35) -> 97.94 | BD35: =AG35*Factors!AG$6+AF35*Factors!AF$6+AH35*Factors!AH$6 -> 0 | BE35: =BC35+BD35 -> 97.94
A36: Thorite | B36: (Th,U)SiO4 | C36: 16.47 | D36: 0 | H36: 0 | J36: 0 | N36: 0 | R36: 0 | AE36: 0 | AI36: 71.61 | AJ36: 0 | AN36: 0 | BC36: =SUM(C36:BB36) -> 88.08 | BD36: =AG36*Factors!AG$6+AF36*Factors!AF$6+AH36*Factors!AH$6 -> 0 | BE36: =BC36+BD36 -> 88.08
A37: Cryolite | B37: Na3AlF6 | H37: 24.28 | S37: 43.69 | AF37: 54.28 | BC37: =SUM(C37:BB37) -> 122.25 | BD37: =AG37*Factors!AG$6+AF37*Factors!AF$6+AH37*Factors!AH$6 -> -22.855229 | BE37: =BC37+BD37 -> 99.394771
A38: Cassiterite | B38: SnO2 | C38: 0 | D38: 0 | G38: 99.26 | J38: 0 | X38: 0 | Y38: 0 | Z38: 0 | BC38: =SUM(C38:BB38) -> 99.26 | BD38: =AG38*Factors!AG$6+AF38*Factors!AF$6+AH38*Factors!AH$6 -> 0 | BE38: =BC38+BD38 -> 99.26
A39: Nepheline | B39: (Na,K)AlSiO4 | C39: 43.55 | H39: 34.66 | N39: 0.05 | O39: 4.44 | S39: 12.09 | T39: 4.87 | AE39: 0.5 | BC39: =SUM(C39:BB39) -> 100.16 | BD39: =AG39*Factors!AG$6+AF39*Factors!AF$6+AH39*Factors!AH$6 -> 0 | BE39: =BC39+BD39 -> 100.16
A40: Hendricksite (Zn-mica) | B40: K(Zn,Mn)3Si3AlO10(OH)2 | C40: 31.58 | D40: 0.32 | H40: 13.6 | I40: 2.25 | J40: 0 | K40: 12.28 | L40: 19.8 | N40: 2.7 | O40: 0 | Q40: 0.3 | S40: 0.1 | T40: 7.91 | AE40: 3.95 | AF40: 0 | BC40: =SUM(C40:BB40) -> 94.79 | BD40: =AG40*Factors!AG$6+AF40*Factors!AF$6+AH40*Factors!AH$6 -> 0 | BE40: =BC40+BD40 -> 94.79
...

Sheet Oxides_max
A1: Mineral | B1: Ideal formula | C1: SiO2 | D1: TiO2 | E1: ZrO2 | F1: HfO2 | G1: SnO2 | H1: Al2O3 | I1: Fe2O3 | J1: FeO | K1: MnO | L1: ZnO | M1: Cu2O | N1: MgO | O1: CaO | P1: SrO | Q1: BaO | R1: PbO | S1: Na2O | T1: K2O | U1: Li2O | V1: B2O3 | W1: BeO | X1: Nb2O5 | Y1: Ta2O5 | Z1: WO3 | AA1: P2O5 | AB1: As2O5 | AC1: SO3 | AD1: CO2 | AE1: H2O | AF1: F | AG1: Cl | AH1: S (sulfide) | AI1: ThO2 | AJ1: UO2 | AK1: Sc2O3 | AL1: Y2O3 | AM1: La2O3 | AN1: Ce2O3 | AO1: CeO2 | AP1: Pr2O3 | AQ1: Nd2O3 | AR1: Sm2O3 | AS1: Eu2O3 | AT1: Gd2O3 | AU1: Tb2O3 | AV1: Dy2O3 | AW1: Ho2O3 | AX1: Er2O3 | AY1: Tm2O3 | AZ1: Yb2O3 | BA1: Lu2O3 | BB1: Bi2O3 | BC1: Sum of oxides | BD1: − O≡F,Cl,S | BE1: Total (wt%)
A2: Monazite-(Ce) | B2: (Ce,La,Nd,Th)PO4 | C2: 5 | H2: 0.3 | J2: 0.5 | O2: 4 | P2: 0.3 | R2: 1.5 | AA2: 31 | AC2: 0.5 | AI2: 20 | AJ2: 2 | AL2: 4 | AM2: 24 | AN2: 37 | AP2: 4 | AQ2: 14 | AR2: 4 | AS2: 0.3 | AT2: 3 | AU2: 0.3 | AV2: 1.5 | AW2: 0.3 | AX2: 0.5 | AY2: 0.05 | AZ2: 0.3 | BA2: 0.05 | BC2: =SUM(C2:BB2) -> 158.4 | BD2: =AG2*Factors!AG$6+AF2*Factors!AF$6+AH2*Factors!AH$6 -> 0 | BE2: =BC2+BD2 -> 158.4
A3: Bastnäsite-(Ce) | B3: (Ce,La)(CO3)F | C3: 1 | J3: 0.6 | O3: 2.5 | P3: 1 | Q3: 1 | AA3: 0.6 | AD3: 21 | AE3: 2 | AF3: 9.5 | AI3: 2.5 | AJ3: 0.05 | AL3: 1.5 | AM3: 37.3 | AN3: 42 | AP3: 5 | AQ3: 16 | AR3: 2.5 | AS3: 0.4 | AT3: 1.2 | AV3: 0.4 | BC3: =SUM(C3:BB3) -> 148.05 | BD3: =AG3*Factors!AG$6+AF3*Factors!AF$6+AH3*Factors!AH$6 -> -4.0000862 | BE3: =BC3+BD3 -> 144.04991
A4: Xenotime-(Y) | B4: YPO4 | C4: 2 | H4: 0.2 | J4: 0.5 | O4: 0.6 | R4: 0.3 | AA4: 36 | AI4: 3 | AJ4: 5 | AL4: 52 | AM4: 0.1 | AN4: 0.3 | AP4: 0.1 | AQ4: 0.5 | AR4: 1 | AS4: 0.2 | AT4: 4.5 | AU4: 1 | AV4: 7 | AW4: 1.8 | AX4: 5.5 | AY4: 1 | AZ4: 7 | BA4: 1.5 | BC4: =SUM(C4:BB4) -> 131.1 | BD4: =AG4*Factors!AG$6+AF4*Factors!AF$6+AH4*Factors!AH$6 -> 0 | BE4: =BC4+BD4 -> 131.1
A5: Parisite-(Ce) | B5: CaCe2(CO3)3F2 | C5: 0.5 | J5: 0.3 | O5: 12 | P5: 1 | Q5: 0.5 | S5: 0.2 | AD5: 25.5 | AF5: 7.5 | AI5: 1.5 | AJ5: 0.05 | AL5: 2 | AM5: 20 | AN5: 33 | AP5: 4 | AQ5: 13.5 | AR5: 2.5 | AS5: 0.5 | AT5: 1.5 | AV5: 0.6 | BC5: =SUM(C5:BB5) -> 126.65 | BD5: =AG5*Factors!AG$6+AF5*Factors!AF$6+AH5*Factors!AH$6 -> -3.1579628 | BE5: =BC5+BD5 -> 123.49204
